Workbook

Sheet Member Evaluation
A1: OR - Committee Members Evaluation
A2: Evaluee | B2: Field Visits Entered | C2: FIELD VISITS (30 pts) | R2: Field Visits Total /30 | S2: Meetings Entered | T2: MEETINGS (30 pts) | AI2: Meetings Total /30 | AJ2: Tasks Entered | AK2: TASKS (20 pts) | CS2: Tasks Score | CW2: Interaction /10 | CX2: Respect Hierarchy /10 | CY2: Bonus /10 | CZ2: TOTAL /110 | DA2: % | DB2: Grade
A3: Gov Name
A4: Name | C4: 1 | D4: 2 | E4: 3 | F4: 4 | G4: 5 | H4: 6 | I4: 7 | J4: 8 | K4: 9 | L4: 10 | M4: 11 | N4: 12 | O4: 13 | P4: 14 | Q4: 15 | T4: 1 | U4: 2 | V4: 3 | W4: 4 | X4: 5 | Y4: 6 | Z4: 7 | AA4: 8 | AB4: 9 | AC4: 10 | AD4: 11 | AE4: 12 | AF4: 13 | AG4: 14 | AH4: 15 | AK4: T | AL4: Q | AM4: D | AN4: T | AO4: Q | AP4: D | AQ4: T | AR4: Q | AS4: D | AT4: T | AU4: Q | AV4: D | AW4: T | AX4: Q | AY4: D | AZ4: T | BA4: Q | BB4: D | BC4: T | BD4: Q | BE4: D | BF4: T | BG4: Q | BH4: D | BI4: T | BJ4: Q | BK4: D | BL4: T | BM4: Q | BN4: D | BO4: T | BP4: Q | BQ4: D | BR4: T | BS4: Q | BT4: D | BU4: T | BV4: Q | BW4: D | BX4: T | BY4: Q | BZ4: D | CA4: T | CB4: Q | CC4: D | CD4: T | CE4: Q | CF4: D | CG4: T | CH4: Q | CI4: D | CJ4: T | CK4: Q | CL4: D | CM4: T | CN4: Q | CO4: D | CP4: T | CQ4: Q | CR4: D | CS4: Submission | CT4: Quality | CU4: Deadline | CV4: Tasks Total
B5: =IF(COUNTA(C3,D3,E3,F3,G3,H3,I3,J3,K3,L3,M3,N3,O3,P3,Q3)=0,"",COUNTA(C3,D3,E3,F3,G3,H3,I3,J3,K3,L3,M3,N3,O3,P3,Q3)) | R5: =IFERROR(SUM(C5,D5,E5,F5,G5,H5,I5,J5,K5,L5,M5,N5,O5,P5,Q5)/B5*30,0) -> 0 | S5: =IF(COUNTA(T3,U3,V3,W3,X3,Y3,Z3,AA3,AB3,AC3,AD3,AE3,AF3,AG3,AH3)=0,"",COUNTA(T3,U3,V3,W3,X3,Y3,Z3,AA3,AB3,AC3,AD3,AE3,AF3,AG3,AH3)) | AI5: =IFERROR(SUM(T5,U5,V5,W5,X5,Y5,Z5,AA5,AB5,AC5,AD5,AE5,AF5,AG5,AH5)/S5*30,0) -> 0 | AJ5: =IF(COUNTA(AK3,AN3,AQ3,AT3,AW3,AZ3,BC3,BF3,BI3,BL3,BO3,BR3,BU3,BX3,CA3,CD3,CG3,CJ3,CM3,CP3)=0,"",COUNTA(AK3,AN3,AQ3,AT3,AW3,AZ3,BC3,BF3,BI3,BL3,BO3,BR3,BU3,BX3,CA3,CD3,CG3,CJ3,CM3,CP3)) | CS5: =IFERROR(SUM(AK5,AN5,AQ5,AT5,AW5,AZ5,BC5,BF5,BI5,BL5,BO5,BR5,BU5,BX5,CA5,CD5,CG5,CJ5,CM5,CP5)/AJ5*10,0) -> 0 | CT5: =IFERROR(SUM(AL5,AO5,AR5,AU5,AX5,BA5,BD5,BG5,BJ5,BM5,BP5,BS5,BV5,BY5,CB5,CE5,CH5,CK5,CN5,CQ5)/AJ5/5*5,0) -> 0 | CU5: =IFERROR(SUM(AM5,AP5,AS5,AV5,AY5,BB5,BE5,BH5,BK5,BN5,BQ5,BT5,BW5,BZ5,CC5,CF5,CI5,CL5,CO5,CR5)/AJ5*5,0) -> 0 | CV5: =ROUND(SUM(CS5,CT5,CU5),2) -> 0 | CZ5: =ROUND(SUM(R5,AI5,CV5,CW5,CX5,CY5),2) -> 0 | DA5: =ROUND(CZ5/110*100,1) -> 0 | DB5: =IF(CZ5>=90,"A",IF(CZ5>=80,"B",IF(CZ5>=70,"C",IF(CZ5>=60,"D",IF(CZ5>0,"F"," "))))) | DE5: =IF(A5="","",DA5-ROW()/100000000)
B6: =IF(COUNTA(C3,D3,E3,F3,G3,H3,I3,J3,K3,L3,M3,N3,O3,P3,Q3)=0,"",COUNTA(C3,D3,E3,F3,G3,H3,I3,J3,K3,L3,M3,N3,O3,P3,Q3)) | R6: =IFERROR(SUM(C6,D6,E6,F6,G6,H6,I6,J6,K6,L6,M6,N6,O6,P6,Q6)/B6*30,0) -> 0 | S6: =IF(COUNTA(T3,U3,V3,W3,X3,Y3,Z3,AA3,AB3,AC3,AD3,AE3,AF3,AG3,AH3)=0,"",COUNTA(T3,U3,V3,W3,X3,Y3,Z3,AA3,AB3,AC3,AD3,AE3,AF3,AG3,AH3)) | AI6: =IFERROR(SUM(T6,U6,V6,W6,X6,Y6,Z6,AA6,AB6,AC6,AD6,AE6,AF6,AG6,AH6)/S6*30,0) -> 0 | AJ6: =IF(COUNTA(AK3,AN3,AQ3,AT3,AW3,AZ3,BC3,BF3,BI3,BL3,BO3,BR3,BU3,BX3,CA3,CD3,CG3,CJ3,CM3,CP3)=0,"",COUNTA(AK3,AN3,AQ3,AT3,AW3,AZ3,BC3,BF3,BI3,BL3,BO3,BR3,BU3,BX3,CA3,CD3,CG3,CJ3,CM3,CP3)) | CS6: =IFERROR(SUM(AK6,AN6,AQ6,AT6,AW6,AZ6,BC6,BF6,BI6,BL6,BO6,BR6,BU6,BX6,CA6,CD6,CG6,CJ6,CM6,CP6)/AJ6*10,0) -> 0 | CT6: =IFERROR(SUM(AL6,AO6,AR6,AU6,AX6,BA6,BD6,BG6,BJ6,BM6,BP6,BS6,BV6,BY6,CB6,CE6,CH6,CK6,CN6,CQ6)/AJ6/5*5,0) -> 0 | CU6: =IFERROR(SUM(AM6,AP6,AS6,AV6,AY6,BB6,BE6,BH6,BK6,BN6,BQ6,BT6,BW6,BZ6,CC6,CF6,CI6,CL6,CO6,CR6)/AJ6*5,0) -> 0 | CV6: =ROUND(SUM(CS6,CT6,CU6),2) -> 0 | CZ6: =ROUND(SUM(R6,AI6,CV6,CW6,CX6,CY6),2) -> 0 | DA6: =ROUND(CZ6/110*100,1) -> 0 | DB6: =IF(CZ6>=90,"A",IF(CZ6>=80,"B",IF(CZ6>=70,"C",IF(CZ6>=60,"D",IF(CZ6>0,"F"," "))))) | DE6: =IF(A6="","",DA6-ROW()/100000000)
B7: =IF(COUNTA(C3,D3,E3,F3,G3,H3,I3,J3,K3,L3,M3,N3,O3,P3,Q3)=0,"",COUNTA(C3,D3,E3,F3,G3,H3,I3,J3,K3,L3,M3,N3,O3,P3,Q3)) | R7: =IFERROR(SUM(C7,D7,E7,F7,G7,H7,I7,J7,K7,L7,M7,N7,O7,P7,Q7)/B7*30,0) -> 0 | S7: =IF(COUNTA(T3,U3,V3,W3,X3,Y3,Z3,AA3,AB3,AC3,AD3,AE3,AF3,AG3,AH3)=0,"",COUNTA(T3,U3,V3,W3,X3,Y3,Z3,AA3,AB3,AC3,AD3,AE3,AF3,AG3,AH3)) | AI7: =IFERROR(SUM(T7,U7,V7,W7,X7,Y7,Z7,AA7,AB7,AC7,AD7,AE7,AF7,AG7,AH7)/S7*30,0) -> 0 | AJ7: =IF(COUNTA(AK3,AN3,AQ3,AT3,AW3,AZ3,BC3,BF3,BI3,BL3,BO3,BR3,BU3,BX3,CA3,CD3,CG3,CJ3,CM3,CP3)=0,"",COUNTA(AK3,AN3,AQ3,AT3,AW3,AZ3,BC3,BF3,BI3,BL3,BO3,BR3,BU3,BX3,CA3,CD3,CG3,CJ3,CM3,CP3)) | CS7: =IFERROR(SUM(AK7,AN7,AQ7,AT7,AW7,AZ7,BC7,BF7,BI7,BL7,BO7,BR7,BU7,BX7,CA7,CD7,CG7,CJ7,CM7,CP7)/AJ7*10,0) -> 0 | CT7: =IFERROR(SUM(AL7,AO7,AR7,AU7,AX7,BA7,BD7,BG7,BJ7,BM7,BP7,BS7,BV7,BY7,CB7,CE7,CH7,CK7,CN7,CQ7)/AJ7/5*5,0) -> 0 | CU7: =IFERROR(SUM(AM7,AP7,AS7,AV7,AY7,BB7,BE7,BH7,BK7,BN7,BQ7,BT7,BW7,BZ7,CC7,CF7,CI7,CL7,CO7,CR7)/AJ7*5,0) -> 0 | CV7: =ROUND(SUM(CS7,CT7,CU7),2) -> 0 | CZ7: =ROUND(SUM(R7,AI7,CV7,CW7,CX7,CY7),2) -> 0 | DA7: =ROUND(CZ7/110*100,1) -> 0 | DB7: =IF(CZ7>=90,"A",IF(CZ7>=80,"B",IF(CZ7>=70,"C",IF(CZ7>=60,"D",IF(CZ7>0,"F"," "))))) | DE7: =IF(A7="","",DA7-ROW()/100000000)
B8: =IF(COUNTA(C3,D3,E3,F3,G3,H3,I3,J3,K3,L3,M3,N3,O3,P3,Q3)=0,"",COUNTA(C3,D3,E3,F3,G3,H3,I3,J3,K3,L3,M3,N3,O3,P3,Q3)) | R8: =IFERROR(SUM(C8,D8,E8,F8,G8,H8,I8,J8,K8,L8,M8,N8,O8,P8,Q8)/B8*30,0) -> 0 | S8: =IF(COUNTA(T3,U3,V3,W3,X3,Y3,Z3,AA3,AB3,AC3,AD3,AE3,AF3,AG3,AH3)=0,"",COUNTA(T3,U3,V3,W3,X3,Y3,Z3,AA3,AB3,AC3,AD3,AE3,AF3,AG3,AH3)) | AI8: =IFERROR(SUM(T8,U8,V8,W8,X8,Y8,Z8,AA8,AB8,AC8,AD8,AE8,AF8,AG8,AH8)/S8*30,0) -> 0 | AJ8: =IF(COUNTA(AK3,AN3,AQ3,AT3,AW3,AZ3,BC3,BF3,BI3,BL3,BO3,BR3,BU3,BX3,CA3,CD3,CG3,CJ3,CM3,CP3)=0,"",COUNTA(AK3,AN3,AQ3,AT3,AW3,AZ3,BC3,BF3,BI3,BL3,BO3,BR3,BU3,BX3,CA3,CD3,CG3,CJ3,CM3,CP3)) | CS8: =IFERROR(SUM(AK8,AN8,AQ8,AT8,AW8,AZ8,BC8,BF8,BI8,BL8,BO8,BR8,BU8,BX8,CA8,CD8,CG8,CJ8,CM8,CP8)/AJ8*10,0) -> 0 | CT8: =IFERROR(SUM(AL8,AO8,AR8,AU8,AX8,BA8,BD8,BG8,BJ8,BM8,BP8,BS8,BV8,BY8,CB8,CE8,CH8,CK8,CN8,CQ8)/AJ8/5*5,0) -> 0 | CU8: =IFERROR(SUM(AM8,AP8,AS8,AV8,AY8,BB8,BE8,BH8,BK8,BN8,BQ8,BT8,BW8,BZ8,CC8,CF8,CI8,CL8,CO8,CR8)/AJ8*5,0) -> 0 | CV8: =ROUND(SUM(CS8,CT8,CU8),2) -> 0 | CZ8: =ROUND(SUM(R8,AI8,CV8,CW8,CX8,CY8),2) -> 0 | DA8: =ROUND(CZ8/110*100,1) -> 0 | DB8: =IF(CZ8>=90,"A",IF(CZ8>=80,"B",IF(CZ8>=70,"C",IF(CZ8>=60,"D",IF(CZ8>0,"F"," "))))) | DE8: =IF(A8="","",DA8-ROW()/100000000)
B9: =IF(COUNTA(C3,D3,E3,F3,G3,H3,I3,J3,K3,L3,M3,N3,O3,P3,Q3)=0,"",COUNTA(C3,D3,E3,F3,G3,H3,I3,J3,K3,L3,M3,N3,O3,P3,Q3)) | R9: =IFERROR(SUM(C9,D9,E9,F9,G9,H9,I9,J9,K9,L9,M9,N9,O9,P9,Q9)/B9*30,0) -> 0 | S9: =IF(COUNTA(T3,U3,V3,W3,X3,Y3,Z3,AA3,AB3,AC3,AD3,AE3,AF3,AG3,AH3)=0,"",COUNTA(T3,U3,V3,W3,X3,Y3,Z3,AA3,AB3,AC3,AD3,AE3,AF3,AG3,AH3)) | AI9: =IFERROR(SUM(T9,U9,V9,W9,X9,Y9,Z9,AA9,AB9,AC9,AD9,AE9,AF9,AG9,AH9)/S9*30,0) -> 0 | AJ9: =IF(COUNTA(AK3,AN3,AQ3,AT3,AW3,AZ3,BC3,BF3,BI3,BL3,BO3,BR3,BU3,BX3,CA3,CD3,CG3,CJ3,CM3,CP3)=0,"",COUNTA(AK3,AN3,AQ3,AT3,AW3,AZ3,BC3,BF3,BI3,BL3,BO3,BR3,BU3,BX3,CA3,CD3,CG3,CJ3,CM3,CP3)) | CS9: =IFERROR(SUM(AK9,AN9,AQ9,AT9,AW9,AZ9,BC9,BF9,BI9,BL9,BO9,BR9,BU9,BX9,CA9,CD9,CG9,CJ9,CM9,CP9)/AJ9*10,0) -> 0 | CT9: =IFERROR(SUM(AL9,AO9,AR9,AU9,AX9,BA9,BD9,BG9,BJ9,BM9,BP9,BS9,BV9,BY9,CB9,CE9,CH9,CK9,CN9,CQ9)/AJ9/5*5,0) -> 0 | CU9: =IFERROR(SUM(AM9,AP9,AS9,AV9,AY9,BB9,BE9,BH9,BK9,BN9,BQ9,BT9,BW9,BZ9,CC9,CF9,CI9,CL9,CO9,CR9)/AJ9*5,0) -> 0 | CV9: =ROUND(SUM(CS9,CT9,CU9),2) -> 0 | CZ9: =ROUND(SUM(R9,AI9,CV9,CW9,CX9,CY9),2) -> 0 | DA9: =ROUND(CZ9/110*100,1) -> 0 | DB9: =IF(CZ9>=90,"A",IF(CZ9>=80,"B",IF(CZ9>=70,"C",IF(CZ9>=60,"D",IF(CZ9>0,"F"," "))))) | DE9: =IF(A9="","",DA9-ROW()/100000000)
B10: =IF(COUNTA(C3,D3,E3,F3,G3,H3,I3,J3,K3,L3,M3,N3,O3,P3,Q3)=0,"",COUNTA(C3,D3,E3,F3,G3,H3,I3,J3,K3,L3,M3,N3,O3,P3,Q3)) | R10: =IFERROR(SUM(C10,D10,E10,F10,G10,H10,I10,J10,K10,L10,M10,N10,O10,P10,Q10)/B10*30,0) -> 0 | S10: =IF(COUNTA(T3,U3,V3,W3,X3,Y3,Z3,AA3,AB3,AC3,AD3,AE3,AF3,AG3,AH3)=0,"",COUNTA(T3,U3,V3,W3,X3,Y3,Z3,AA3,AB3,AC3,AD3,AE3,AF3,AG3,AH3)) | AI10: =IFERROR(SUM(T10,U10,V10,W10,X10,Y10,Z10,AA10,AB10,AC10,AD10,AE10,AF10,AG10,AH10)/S10*30,0) -> 0 | AJ10: =IF(COUNTA(AK3,AN3,AQ3,AT3,AW3,AZ3,BC3,BF3,BI3,BL3,BO3,BR3,BU3,BX3,CA3,CD3,CG3,CJ3,CM3,CP3)=0,"",COUNTA(AK3,AN3,AQ3,AT3,AW3,AZ3,BC3,BF3,BI3,BL3,BO3,BR3,BU3,BX3,CA3,CD3,CG3,CJ3,CM3,CP3)) | CS10: =IFERROR(SUM(AK10,AN10,AQ10,AT10,AW10,AZ10,BC10,BF10,BI10,BL10,BO10,BR10,BU10,BX10,CA10,CD10,CG10,CJ10,CM10,CP10)/AJ10*10,0) -> 0 | CT10: =IFERROR(SUM(AL10,AO10,AR10,AU10,AX10,BA10,BD10,BG10,BJ10,BM10,BP10,BS10,BV10,BY10,CB10,CE10,CH10,CK10,CN10,CQ10)/AJ10/5*5,0) -> 0 | CU10: =IFERROR(SUM(AM10,AP10,AS10,AV10,AY10,BB10,BE10,BH10,BK10,BN10,BQ10,BT10,BW10,BZ10,CC10,CF10,CI10,CL10,CO10,CR10)/AJ10*5,0) -> 0 | CV10: =ROUND(SUM(CS10,CT10,CU10),2) -> 0 | CZ10: =ROUND(SUM(R10,AI10,CV10,CW10,CX10,CY10),2) -> 0 | DA10: =ROUND(CZ10/110*100,1) -> 0 | DB10: =IF(CZ10>=90,"A",IF(CZ10>=80,"B",IF(CZ10>=70,"C",IF(CZ10>=60,"D",IF(CZ10>0,"F"," "))))) | DE10: =IF(A10="","",DA10-ROW()/100000000)
B11: =IF(COUNTA(C3,D3,E3,F3,G3,H3,I3,J3,K3,L3,M3,N3,O3,P3,Q3)=0,"",COUNTA(C3,D3,E3,F3,G3,H3,I3,J3,K3,L3,M3,N3,O3,P3,Q3)) | R11: =IFERROR(SUM(C11,D11,E11,F11,G11,H11,I11,J11,K11,L11,M11,N11,O11,P11,Q11)/B11*30,0) -> 0 | S11: =IF(COUNTA(T3,U3,V3,W3,X3,Y3,Z3,AA3,AB3,AC3,AD3,AE3,AF3,AG3,AH3)=0,"",COUNTA(T3,U3,V3,W3,X3,Y3,Z3,AA3,AB3,AC3,AD3,AE3,AF3,AG3,AH3)) | AI11: =IFERROR(SUM(T11,U11,V11,W11,X11,Y11,Z11,AA11,AB11,AC11,AD11,AE11,AF11,AG11,AH11)/S11*30,0) -> 0 | AJ11: =IF(COUNTA(AK3,AN3,AQ3,AT3,AW3,AZ3,BC3,BF3,BI3,BL3,BO3,BR3,BU3,BX3,CA3,CD3,CG3,CJ3,CM3,CP3)=0,"",COUNTA(AK3,AN3,AQ3,AT3,AW3,AZ3,BC3,BF3,BI3,BL3,BO3,BR3,BU3,BX3,CA3,CD3,CG3,CJ3,CM3,CP3)) | CS11: =IFERROR(SUM(AK11,AN11,AQ11,AT11,AW11,AZ11,BC11,BF11,BI11,BL11,BO11,BR11,BU11,BX11,CA11,CD11,CG11,CJ11,CM11,CP11)/AJ11*10,0) -> 0 | CT11: =IFERROR(SUM(AL11,AO11,AR11,AU11,AX11,BA11,BD11,BG11,BJ11,BM11,BP11,BS11,BV11,BY11,CB11,CE11,CH11,CK11,CN11,CQ11)/AJ11/5*5,0) -> 0 | CU11: =IFERROR(SUM(AM11,AP11,AS11,AV11,AY11,BB11,BE11,BH11,BK11,BN11,BQ11,BT11,BW11,BZ11,CC11,CF11,CI11,CL11,CO11,CR11)/AJ11*5,0) -> 0 | CV11: =ROUND(SUM(CS11,CT11,CU11),2) -> 0 | CZ11: =ROUND(SUM(R11,AI11,CV11,CW11,CX11,CY11),2) -> 0 | DA11: =ROUND(CZ11/110*100,1) -> 0 | DB11: =IF(CZ11>=90,"A",IF(CZ11>=80,"B",IF(CZ11>=70,"C",IF(CZ11>=60,"D",IF(CZ11>0,"F"," "))))) | DE11: =IF(A11="","",DA11-ROW()/100000000)
B12: =IF(COUNTA(C3,D3,E3,F3,G3,H3,I3,J3,K3,L3,M3,N3,O3,P3,Q3)=0,"",COUNTA(C3,D3,E3,F3,G3,H3,I3,J3,K3,L3,M3,N3,O3,P3,Q3)) | R12: =IFERROR(SUM(C12,D12,E12,F12,G12,H12,I12,J12,K12,L12,M12,N12,O12,P12,Q12)/B12*30,0) -> 0 | S12: =IF(COUNTA(T3,U3,V3,W3,X3,Y3,Z3,AA3,AB3,AC3,AD3,AE3,AF3,AG3,AH3)=0,"",COUNTA(T3,U3,V3,W3,X3,Y3,Z3,AA3,AB3,AC3,AD3,AE3,AF3,AG3,AH3)) | AI12: =IFERROR(SUM(T12,U12,V12,W12,X12,Y12,Z12,AA12,AB12,AC12,AD12,AE12,AF12,AG12,AH12)/S12*30,0) -> 0 | AJ12: =IF(COUNTA(AK3,AN3,AQ3,AT3,AW3,AZ3,BC3,BF3,BI3,BL3,BO3,BR3,BU3,BX3,CA3,CD3,CG3,CJ3,CM3,CP3)=0,"",COUNTA(AK3,AN3,AQ3,AT3,AW3,AZ3,BC3,BF3,BI3,BL3,BO3,BR3,BU3,BX3,CA3,CD3,CG3,CJ3,CM3,CP3)) | CS12: =IFERROR(SUM(AK12,AN12,AQ12,AT12,AW12,AZ12,BC12,BF12,BI12,BL12,BO12,BR12,BU12,BX12,CA12,CD12,CG12,CJ12,CM12,CP12)/AJ12*10,0) -> 0 | CT12: =IFERROR(SUM(AL12,AO12,AR12,AU12,AX12,BA12,BD12,BG12,BJ12,BM12,BP12,BS12,BV12,BY12,CB12,CE12,CH12,CK12,CN12,CQ12)/AJ12/5*5,0) -> 0 | CU12: =IFERROR(SUM(AM12,AP12,AS12,AV12,AY12,BB12,BE12,BH12,BK12,BN12,BQ12,BT12,BW12,BZ12,CC12,CF12,CI12,CL12,CO12,CR12)/AJ12*5,0) -> 0 | CV12: =ROUND(SUM(CS12,CT12,CU12),2) -> 0 | CZ12: =ROUND(SUM(R12,AI12,CV12,CW12,CX12,CY12),2) -> 0 | DA12: =ROUND(CZ12/110*100,1) -> 0 | DB12: =IF(CZ12>=90,"A",IF(CZ12>=80,"B",IF(CZ12>=70,"C",IF(CZ12>=60,"D",IF(CZ12>0,"F"," "))))) | DE12: =IF(A12="","",DA12-ROW()/100000000)
B13: =IF(COUNTA(C3,D3,E3,F3,G3,H3,I3,J3,K3,L3,M3,N3,O3,P3,Q3)=0,"",COUNTA(C3,D3,E3,F3,G3,H3,I3,J3,K3,L3,M3,N3,O3,P3,Q3)) | R13: =IFERROR(SUM(C13,D13,E13,F13,G13,H13,I13,J13,K13,L13,M13,N13,O13,P13,Q13)/B13*30,0) -> 0 | S13: =IF(COUNTA(T3,U3,V3,W3,X3,Y3,Z3,AA3,AB3,AC3,AD3,AE3,AF3,AG3,AH3)=0,"",COUNTA(T3,U3,V3,W3,X3,Y3,Z3,AA3,AB3,AC3,AD3,AE3,AF3,AG3,AH3)) | AI13: =IFERROR(SUM(T13,U13,V13,W13,X13,Y13,Z13,AA13,AB13,AC13,AD13,AE13,AF13,AG13,AH13)/S13*30,0) -> 0 | AJ13: =IF(COUNTA(AK3,AN3,AQ3,AT3,AW3,AZ3,BC3,BF3,BI3,BL3,BO3,BR3,BU3,BX3,CA3,CD3,CG3,CJ3,CM3,CP3)=0,"",COUNTA(AK3,AN3,AQ3,AT3,AW3,AZ3,BC3,BF3,BI3,BL3,BO3,BR3,BU3,BX3,CA3,CD3,CG3,CJ3,CM3,CP3)) | CS13: =IFERROR(SUM(AK13,AN13,AQ13,AT13,AW13,AZ13,BC13,BF13,BI13,BL13,BO13,BR13,BU13,BX13,CA13,CD13,CG13,CJ13,CM13,CP13)/AJ13*10,0) -> 0 | CT13: =IFERROR(SUM(AL13,AO13,AR13,AU13,AX13,BA13,BD13,BG13,BJ13,BM13,BP13,BS13,BV13,BY13,CB13,CE13,CH13,CK13,CN13,CQ13)/AJ13/5*5,0) -> 0 | CU13: =IFERROR(SUM(AM13,AP13,AS13,AV13,AY13,BB13,BE13,BH13,BK13,BN13,BQ13,BT13,BW13,BZ13,CC13,CF13,CI13,CL13,CO13,CR13)/AJ13*5,0) -> 0 | CV13: =ROUND(SUM(CS13,CT13,CU13),2) -> 0 | CZ13: =ROUND(SUM(R13,AI13,CV13,CW13,CX13,CY13),2) -> 0 | DA13: =ROUND(CZ13/110*100,1) -> 0 | DB13: =IF(CZ13>=90,"A",IF(CZ13>=80,"B",IF(CZ13>=70,"C",IF(CZ13>=60,"D",IF(CZ13>0,"F"," "))))) | DE13: =IF(A13="","",DA13-ROW()/100000000)
B14: =IF(COUNTA(C3,D3,E3,F3,G3,H3,I3,J3,K3,L3,M3,N3,O3,P3,Q3)=0,"",COUNTA(C3,D3,E3,F3,G3,H3,I3,J3,K3,L3,M3,N3,O3,P3,Q3)) | R14: =IFERROR(SUM(C14,D14,E14,F14,G14,H14,I14,J14,K14,L14,M14,N14,O14,P14,Q14)/B14*30,0) -> 0 | S14: =IF(COUNTA(T3,U3,V3,W3,X3,Y3,Z3,AA3,AB3,AC3,AD3,AE3,AF3,AG3,AH3)=0,"",COUNTA(T3,U3,V3,W3,X3,Y3,Z3,AA3,AB3,AC3,AD3,AE3,AF3,AG3,AH3)) | AI14: =IFERROR(SUM(T14,U14,V14,W14,X14,Y14,Z14,AA14,AB14,AC14,AD14,AE14,AF14,AG14,AH14)/S14*30,0) -> 0 | AJ14: =IF(COUNTA(AK3,AN3,AQ3,AT3,AW3,AZ3,BC3,BF3,BI3,BL3,BO3,BR3,BU3,BX3,CA3,CD3,CG3,CJ3,CM3,CP3)=0,"",COUNTA(AK3,AN3,AQ3,AT3,AW3,AZ3,BC3,BF3,BI3,BL3,BO3,BR3,BU3,BX3,CA3,CD3,CG3,CJ3,CM3,CP3)) | CS14: =IFERROR(SUM(AK14,AN14,AQ14,AT14,AW14,AZ14,BC14,BF14,BI14,BL14,BO14,BR14,BU14,BX14,CA14,CD14,CG14,CJ14,CM14,CP14)/AJ14*10,0) -> 0 | CT14: =IFERROR(SUM(AL14,AO14,AR14,AU14,AX14,BA14,BD14,BG14,BJ14,BM14,BP14,BS14,BV14,BY14,CB14,CE14,CH14,CK14,CN14,CQ14)/AJ14/5*5,0) -> 0 | CU14: =IFERROR(SUM(AM14,AP14,AS14,AV14,AY14,BB14,BE14,BH14,BK14,BN14,BQ14,BT14,BW14,BZ14,CC14,CF14,CI14,CL14,CO14,CR14)/AJ14*5,0) -> 0 | CV14: =ROUND(SUM(CS14,CT14,CU14),2) -> 0 | CZ14: =ROUND(SUM(R14,AI14,CV14,CW14,CX14,CY14),2) -> 0 | DA14: =ROUND(CZ14/110*100,1) -> 0 | DB14: =IF(CZ14>=90,"A",IF(CZ14>=80,"B",IF(CZ14>=70,"C",IF(CZ14>=60,"D",IF(CZ14>0,"F"," "))))) | DE14: =IF(A14="","",DA14-ROW()/100000000)
B15: =IF(COUNTA(C3,D3,E3,F3,G3,H3,I3,J3,K3,L3,M3,N3,O3,P3,Q3)=0,"",COUNTA(C3,D3,E3,F3,G3,H3,I3,J3,K3,L3,M3,N3,O3,P3,Q3)) | R15: =IFERROR(SUM(C15,D15,E15,F15,G15,H15,I15,J15,K15,L15,M15,N15,O15,P15,Q15)/B15*30,0) -> 0 | S15: =IF(COUNTA(T3,U3,V3,W3,X3,Y3,Z3,AA3,AB3,AC3,AD3,AE3,AF3,AG3,AH3)=0,"",COUNTA(T3,U3,V3,W3,X3,Y3,Z3,AA3,AB3,AC3,AD3,AE3,AF3,AG3,AH3)) | AI15: =IFERROR(SUM(T15,U15,V15,W15,X15,Y15,Z15,AA15,AB15,AC15,AD15,AE15,AF15,AG15,AH15)/S15*30,0) -> 0 | AJ15: =IF(COUNTA(AK3,AN3,AQ3,AT3,AW3,AZ3,BC3,BF3,BI3,BL3,BO3,BR3,BU3,BX3,CA3,CD3,CG3,CJ3,CM3,CP3)=0,"",COUNTA(AK3,AN3,AQ3,AT3,AW3,AZ3,BC3,BF3,BI3,BL3,BO3,BR3,BU3,BX3,CA3,CD3,CG3,CJ3,CM3,CP3)) | CS15: =IFERROR(SUM(AK15,AN15,AQ15,AT15,AW15,AZ15,BC15,BF15,BI15,BL15,BO15,BR15,BU15,BX15,CA15,CD15,CG15,CJ15,CM15,CP15)/AJ15*10,0) -> 0 | CT15: =IFERROR(SUM(AL15,AO15,AR15,AU15,AX15,BA15,BD15,BG15,BJ15,BM15,BP15,BS15,BV15,BY15,CB15,CE15,CH15,CK15,CN15,CQ15)/AJ15/5*5,0) -> 0 | CU15: =IFERROR(SUM(AM15,AP15,AS15,AV15,AY15,BB15,BE15,BH15,BK15,BN15,BQ15,BT15,BW15,BZ15,CC15,CF15,CI15,CL15,CO15,CR15)/AJ15*5,0) -> 0 | CV15: =ROUND(SUM(CS15,CT15,CU15),2) -> 0 | CZ15: =ROUND(SUM(R15,AI15,CV15,CW15,CX15,CY15),2) -> 0 | DA15: =ROUND(CZ15/110*100,1) -> 0 | DB15: =IF(CZ15>=90,"A",IF(CZ15>=80,"B",IF(CZ15>=70,"C",IF(CZ15>=60,"D",IF(CZ15>0,"F"," "))))) | DE15: =IF(A15="","",DA15-ROW()/100000000)
B16: =IF(COUNTA(C3,D3,E3,F3,G3,H3,I3,J3,K3,L3,M3,N3,O3,P3,Q3)=0,"",COUNTA(C3,D3,E3,F3,G3,H3,I3,J3,K3,L3,M3,N3,O3,P3,Q3)) | R16: =IFERROR(SUM(C16,D16,E16,F16,G16,H16,I16,J16,K16,L16,M16,N16,O16,P16,Q16)/B16*30,0) -> 0 | S16: =IF(COUNTA(T3,U3,V3,W3,X3,Y3,Z3,AA3,AB3,AC3,AD3,AE3,AF3,AG3,AH3)=0,"",COUNTA(T3,U3,V3,W3,X3,Y3,Z3,AA3,AB3,AC3,AD3,AE3,AF3,AG3,AH3)) | AI16: =IFERROR(SUM(T16,U16,V16,W16,X16,Y16,Z16,AA16,AB16,AC16,AD16,AE16,AF16,AG16,AH16)/S16*30,0) -> 0 | AJ16: =IF(COUNTA(AK3,AN3,AQ3,AT3,AW3,AZ3,BC3,BF3,BI3,BL3,BO3,BR3,BU3,BX3,CA3,CD3,CG3,CJ3,CM3,CP3)=0,"",COUNTA(AK3,AN3,AQ3,AT3,AW3,AZ3,BC3,BF3,BI3,BL3,BO3,BR3,BU3,BX3,CA3,CD3,CG3,CJ3,CM3,CP3)) | CS16: =IFERROR(SUM(AK16,AN16,AQ16,AT16,AW16,AZ16,BC16,BF16,BI16,BL16,BO16,BR16,BU16,BX16,CA16,CD16,CG16,CJ16,CM16,CP16)/AJ16*10,0) -> 0 | CT16: =IFERROR(SUM(AL16,AO16,AR16,AU16,AX16,BA16,BD16,BG16,BJ16,BM16,BP16,BS16,BV16,BY16,CB16,CE16,CH16,CK16,CN16,CQ16)/AJ16/5*5,0) -> 0 | CU16: =IFERROR(SUM(AM16,AP16,AS16,AV16,AY16,BB16,BE16,BH16,BK16,BN16,BQ16,BT16,BW16,BZ16,CC16,CF16,CI16,CL16,CO16,CR16)/AJ16*5,0) -> 0 | CV16: =ROUND(SUM(CS16,CT16,CU16),2) -> 0 | CZ16: =ROUND(SUM(R16,AI16,CV16,CW16,CX16,CY16),2) -> 0 | DA16: =ROUND(CZ16/110*100,1) -> 0 | DB16: =IF(CZ16>=90,"A",IF(CZ16>=80,"B",IF(CZ16>=70,"C",IF(CZ16>=60,"D",IF(CZ16>0,"F"," "))))) | DE16: =IF(A16="","",DA16-ROW()/100000000)
B17: =IF(COUNTA(C3,D3,E3,F3,G3,H3,I3,J3,K3,L3,M3,N3,O3,P3,Q3)=0,"",COUNTA(C3,D3,E3,F3,G3,H3,I3,J3,K3,L3,M3,N3,O3,P3,Q3)) | R17: =IFERROR(SUM(C17,D17,E17,F17,G17,H17,I17,J17,K17,L17,M17,N17,O17,P17,Q17)/B17*30,0) -> 0 | S17: =IF(COUNTA(T3,U3,V3,W3,X3,Y3,Z3,AA3,AB3,AC3,AD3,AE3,AF3,AG3,AH3)=0,"",COUNTA(T3,U3,V3,W3,X3,Y3,Z3,AA3,AB3,AC3,AD3,AE3,AF3,AG3,AH3)) | AI17: =IFERROR(SUM(T17,U17,V17,W17,X17,Y17,Z17,AA17,AB17,AC17,AD17,AE17,AF17,AG17,AH17)/S17*30,0) -> 0 | AJ17: =IF(COUNTA(AK3,AN3,AQ3,AT3,AW3,AZ3,BC3,BF3,BI3,BL3,BO3,BR3,BU3,BX3,CA3,CD3,CG3,CJ3,CM3,CP3)=0,"",COUNTA(AK3,AN3,AQ3,AT3,AW3,AZ3,BC3,BF3,BI3,BL3,BO3,BR3,BU3,BX3,CA3,CD3,CG3,CJ3,CM3,CP3)) | CS17: =IFERROR(SUM(AK17,AN17,AQ17,AT17,AW17,AZ17,BC17,BF17,BI17,BL17,BO17,BR17,BU17,BX17,CA17,CD17,CG17,CJ17,CM17,CP17)/AJ17*10,0) -> 0 | CT17: =IFERROR(SUM(AL17,AO17,AR17,AU17,AX17,BA17,BD17,BG17,BJ17,BM17,BP17,BS17,BV17,BY17,CB17,CE17,CH17,CK17,CN17,CQ17)/AJ17/5*5,0) -> 0 | CU17: =IFERROR(SUM(AM17,AP17,AS17,AV17,AY17,BB17,BE17,BH17,BK17,BN17,BQ17,BT17,BW17,BZ17,CC17,CF17,CI17,CL17,CO17,CR17)/AJ17*5,0) -> 0 | CV17: =ROUND(SUM(CS17,CT17,CU17),2) -> 0 | CZ17: =ROUND(SUM(R17,AI17,CV17,CW17,CX17,CY17),2) -> 0 | DA17: =ROUND(CZ17/110*100,1) -> 0 | DB17: =IF(CZ17>=90,"A",IF(CZ17>=80,"B",IF(CZ17>=70,"C",IF(CZ17>=60,"D",IF(CZ17>0,"F"," "))))) | DE17: =IF(A17="","",DA17-ROW()/100000000)
B18: =IF(COUNTA(C3,D3,E3,F3,G3,H3,I3,J3,K3,L3,M3,N3,O3,P3,Q3)=0,"",COUNTA(C3,D3,E3,F3,G3,H3,I3,J3,K3,L3,M3,N3,O3,P3,Q3)) | R18: =IFERROR(SUM(C18,D18,E18,F18,G18,H18,I18,J18,K18,L18,M18,N18,O18,P18,Q18)/B18*30,0) -> 0 | S18: =IF(COUNTA(T3,U3,V3,W3,X3,Y3,Z3,AA3,AB3,AC3,AD3,AE3,AF3,AG3,AH3)=0,"",COUNTA(T3,U3,V3,W3,X3,Y3,Z3,AA3,AB3,AC3,AD3,AE3,AF3,AG3,AH3)) | AI18: =IFERROR(SUM(T18,U18,V18,W18,X18,Y18,Z18,AA18,AB18,AC18,AD18,AE18,AF18,AG18,AH18)/S18*30,0) -> 0 | AJ18: =IF(COUNTA(AK3,AN3,AQ3,AT3,AW3,AZ3,BC3,BF3,BI3,BL3,BO3,BR3,BU3,BX3,CA3,CD3,CG3,CJ3,CM3,CP3)=0,"",COUNTA(AK3,AN3,AQ3,AT3,AW3,AZ3,BC3,BF3,BI3,BL3,BO3,BR3,BU3,BX3,CA3,CD3,CG3,CJ3,CM3,CP3)) | CS18: =IFERROR(SUM(AK18,AN18,AQ18,AT18,AW18,AZ18,BC18,BF18,BI18,BL18,BO18,BR18,BU18,BX18,CA18,CD18,CG18,CJ18,CM18,CP18)/AJ18*10,0) -> 0 | CT18: =IFERROR(SUM(AL18,AO18,AR18,AU18,AX18,BA18,BD18,BG18,BJ18,BM18,BP18,BS18,BV18,BY18,CB18,CE18,CH18,CK18,CN18,CQ18)/AJ18/5*5,0) -> 0 | CU18: =IFERROR(SUM(AM18,AP18,AS18,AV18,AY18,BB18,BE18,BH18,BK18,BN18,BQ18,BT18,BW18,BZ18,CC18,CF18,CI18,CL18,CO18,CR18)/AJ18*5,0) -> 0 | CV18: =ROUND(SUM(CS18,CT18,CU18),2) -> 0 | CZ18: =ROUND(SUM(R18,AI18,CV18,CW18,CX18,CY18),2) -> 0 | DA18: =ROUND(CZ18/110*100,1) -> 0 | DB18: =IF(CZ18>=90,"A",IF(CZ18>=80,"B",IF(CZ18>=70,"C",IF(CZ18>=60,"D",IF(CZ18>0,"F"," "))))) | DE18: =IF(A18="","",DA18-ROW()/100000000)
B19: =IF(COUNTA(C3,D3,E3,F3,G3,H3,I3,J3,K3,L3,M3,N3,O3,P3,Q3)=0,"",COUNTA(C3,D3,E3,F3,G3,H3,I3,J3,K3,L3,M3,N3,O3,P3,Q3)) | R19: =IFERROR(SUM(C19,D19,E19,F19,G19,H19,I19,J19,K19,L19,M19,N19,O19,P19,Q19)/B19*30,0) -> 0 | S19: =IF(COUNTA(T3,U3,V3,W3,X3,Y3,Z3,AA3,AB3,AC3,AD3,AE3,AF3,AG3,AH3)=0,"",COUNTA(T3,U3,V3,W3,X3,Y3,Z3,AA3,AB3,AC3,AD3,AE3,AF3,AG3,AH3)) | AI19: =IFERROR(SUM(T19,U19,V19,W19,X19,Y19,Z19,AA19,AB19,AC19,AD19,AE19,AF19,AG19,AH19)/S19*30,0) -> 0 | AJ19: =IF(COUNTA(AK3,AN3,AQ3,AT3,AW3,AZ3,BC3,BF3,BI3,BL3,BO3,BR3,BU3,BX3,CA3,CD3,CG3,CJ3,CM3,CP3)=0,"",COUNTA(AK3,AN3,AQ3,AT3,AW3,AZ3,BC3,BF3,BI3,BL3,BO3,BR3,BU3,BX3,CA3,CD3,CG3,CJ3,CM3,CP3)) | CS19: =IFERROR(SUM(AK19,AN19,AQ19,AT19,AW19,AZ19,BC19,BF19,BI19,BL19,BO19,BR19,BU19,BX19,CA19,CD19,CG19,CJ19,CM19,CP19)/AJ19*10,0) -> 0 | CT19: =IFERROR(SUM(AL19,AO19,AR19,AU19,AX19,BA19,BD19,BG19,BJ19,BM19,BP19,BS19,BV19,BY19,CB19,CE19,CH19,CK19,CN19,CQ19)/AJ19/5*5,0) -> 0 | CU19: =IFERROR(SUM(AM19,AP19,AS19,AV19,AY19,BB19,BE19,BH19,BK19,BN19,BQ19,BT19,BW19,BZ19,CC19,CF19,CI19,CL19,CO19,CR19)/AJ19*5,0) -> 0 | CV19: =ROUND(SUM(CS19,CT19,CU19),2) -> 0 | CZ19: =ROUND(SUM(R19,AI19,CV19,CW19,CX19,CY19),2) -> 0 | DA19: =ROUND(CZ19/110*100,1) -> 0 | DB19: =IF(CZ19>=90,"A",IF(CZ19>=80,"B",IF(CZ19>=70,"C",IF(CZ19>=60,"D",IF(CZ19>0,"F"," "))))) | DE19: =IF(A19="","",DA19-ROW()/100000000)
B20: =IF(COUNTA(C3,D3,E3,F3,G3,H3,I3,J3,K3,L3,M3,N3,O3,P3,Q3)=0,"",COUNTA(C3,D3,E3,F3,G3,H3,I3,J3,K3,L3,M3,N3,O3,P3,Q3)) | R20: =IFERROR(SUM(C20,D20,E20,F20,G20,H20,I20,J20,K20,L20,M20,N20,O20,P20,Q20)/B20*30,0) -> 0 | S20: =IF(COUNTA(T3,U3,V3,W3,X3,Y3,Z3,AA3,AB3,AC3,AD3,AE3,AF3,AG3,AH3)=0,"",COUNTA(T3,U3,V3,W3,X3,Y3,Z3,AA3,AB3,AC3,AD3,AE3,AF3,AG3,AH3)) | AI20: =IFERROR(SUM(T20,U20,V20,W20,X20,Y20,Z20,AA20,AB20,AC20,AD20,AE20,AF20,AG20,AH20)/S20*30,0) -> 0 | AJ20: =IF(COUNTA(AK3,AN3,AQ3,AT3,AW3,AZ3,BC3,BF3,BI3,BL3,BO3,BR3,BU3,BX3,CA3,CD3,CG3,CJ3,CM3,CP3)=0,"",COUNTA(AK3,AN3,AQ3,AT3,AW3,AZ3,BC3,BF3,BI3,BL3,BO3,BR3,BU3,BX3,CA3,CD3,CG3,CJ3,CM3,CP3)) | CS20: =IFERROR(SUM(AK20,AN20,AQ20,AT20,AW20,AZ20,BC20,BF20,BI20,BL20,BO20,BR20,BU20,BX20,CA20,CD20,CG20,CJ20,CM20,CP20)/AJ20*10,0) -> 0 | CT20: =IFERROR(SUM(AL20,AO20,AR20,AU20,AX20,BA20,BD20,BG20,BJ20,BM20,BP20,BS20,BV20,BY20,CB20,CE20,CH20,CK20,CN20,CQ20)/AJ20/5*5,0) -> 0 | CU20: =IFERROR(SUM(AM20,AP20,AS20,AV20,AY20,BB20,BE20,BH20,BK20,BN20,BQ20,BT20,BW20,BZ20,CC20,CF20,CI20,CL20,CO20,CR20)/AJ20*5,0) -> 0 | CV20: =ROUND(SUM(CS20,CT20,CU20),2) -> 0 | CZ20: =ROUND(SUM(R20,AI20,CV20,CW20,CX20,CY20),2) -> 0 | DA20: =ROUND(CZ20/110*100,1) -> 0 | DB20: =IF(CZ20>=90,"A",IF(CZ20>=80,"B",IF(CZ20>=70,"C",IF(CZ20>=60,"D",IF(CZ20>0,"F"," "))))) | DE20: =IF(A20="","",DA20-ROW()/100000000)
B21: =IF(COUNTA(C3,D3,E3,F3,G3,H3,I3,J3,K3,L3,M3,N3,O3,P3,Q3)=0,"",COUNTA(C3,D3,E3,F3,G3,H3,I3,J3,K3,L3,M3,N3,O3,P3,Q3)) | R21: =IFERROR(SUM(C21,D21,E21,F21,G21,H21,I21,J21,K21,L21,M21,N21,O21,P21,Q21)/B21*30,0) -> 0 | S21: =IF(COUNTA(T3,U3,V3,W3,X3,Y3,Z3,AA3,AB3,AC3,AD3,AE3,AF3,AG3,AH3)=0,"",COUNTA(T3,U3,V3,W3,X3,Y3,Z3,AA3,AB3,AC3,AD3,AE3,AF3,AG3,AH3)) | AI21: =IFERROR(SUM(T21,U21,V21,W21,X21,Y21,Z21,AA21,AB21,AC21,AD21,AE21,AF21,AG21,AH21)/S21*30,0) -> 0 | AJ21: =IF(COUNTA(AK3,AN3,AQ3,AT3,AW3,AZ3,BC3,BF3,BI3,BL3,BO3,BR3,BU3,BX3,CA3,CD3,CG3,CJ3,CM3,CP3)=0,"",COUNTA(AK3,AN3,AQ3,AT3,AW3,AZ3,BC3,BF3,BI3,BL3,BO3,BR3,BU3,BX3,CA3,CD3,CG3,CJ3,CM3,CP3)) | CS21: =IFERROR(SUM(AK21,AN21,AQ21,AT21,AW21,AZ21,BC21,BF21,BI21,BL21,BO21,BR21,BU21,BX21,CA21,CD21,CG21,CJ21,CM21,CP21)/AJ21*10,0) -> 0 | CT21: =IFERROR(SUM(AL21,AO21,AR21,AU21,AX21,BA21,BD21,BG21,BJ21,BM21,BP21,BS21,BV21,BY21,CB21,CE21,CH21,CK21,CN21,CQ21)/AJ21/5*5,0) -> 0 | CU21: =IFERROR(SUM(AM21,AP21,AS21,AV21,AY21,BB21,BE21,BH21,BK21,BN21,BQ21,BT21,BW21,BZ21,CC21,CF21,CI21,CL21,CO21,CR21)/AJ21*5,0) -> 0 | CV21: =ROUND(SUM(CS21,CT21,CU21),2) -> 0 | CZ21: =ROUND(SUM(R21,AI21,CV21,CW21,CX21,CY21),2) -> 0 | DA21: =ROUND(CZ21/110*100,1) -> 0 | DB21: =IF(CZ21>=90,"A",IF(CZ21>=80,"B",IF(CZ21>=70,"C",IF(CZ21>=60,"D",IF(CZ21>0,"F"," "))))) | DE21: =IF(A21="","",DA21-ROW()/100000000)
B22: =IF(COUNTA(C3,D3,E3,F3,G3,H3,I3,J3,K3,L3,M3,N3,O3,P3,Q3)=0,"",COUNTA(C3,D3,E3,F3,G3,H3,I3,J3,K3,L3,M3,N3,O3,P3,Q3)) | R22: =IFERROR(SUM(C22,D22,E22,F22,G22,H22,I22,J22,K22,L22,M22,N22,O22,P22,Q22)/B22*30,0) -> 0 | S22: =IF(COUNTA(T3,U3,V3,W3,X3,Y3,Z3,AA3,AB3,AC3,AD3,AE3,AF3,AG3,AH3)=0,"",COUNTA(T3,U3,V3,W3,X3,Y3,Z3,AA3,AB3,AC3,AD3,AE3,AF3,AG3,AH3)) | AI22: =IFERROR(SUM(T22,U22,V22,W22,X22,Y22,Z22,AA22,AB22,AC22,AD22,AE22,AF22,AG22,AH22)/S22*30,0) -> 0 | AJ22: =IF(COUNTA(AK3,AN3,AQ3,AT3,AW3,AZ3,BC3,BF3,BI3,BL3,BO3,BR3,BU3,BX3,CA3,CD3,CG3,CJ3,CM3,CP3)=0,"",COUNTA(AK3,AN3,AQ3,AT3,AW3,AZ3,BC3,BF3,BI3,BL3,BO3,BR3,BU3,BX3,CA3,CD3,CG3,CJ3,CM3,CP3)) | CS22: =IFERROR(SUM(AK22,AN22,AQ22,AT22,AW22,AZ22,BC22,BF22,BI22,BL22,BO22,BR22,BU22,BX22,CA22,CD22,CG22,CJ22,CM22,CP22)/AJ22*10,0) -> 0 | CT22: =IFERROR(SUM(AL22,AO22,AR22,AU22,AX22,BA22,BD22,BG22,BJ22,BM22,BP22,BS22,BV22,BY22,CB22,CE22,CH22,CK22,CN22,CQ22)/AJ22/5*5,0) -> 0 | CU22: =IFERROR(SUM(AM22,AP22,AS22,AV22,AY22,BB22,BE22,BH22,BK22,BN22,BQ22,BT22,BW22,BZ22,CC22,CF22,CI22,CL22,CO22,CR22)/AJ22*5,0) -> 0 | CV22: =ROUND(SUM(CS22,CT22,CU22),2) -> 0 | CZ22: =ROUND(SUM(R22,AI22,CV22,CW22,CX22,CY22),2) -> 0 | DA22: =ROUND(CZ22/110*100,1) -> 0 | DB22: =IF(CZ22>=90,"A",IF(CZ22>=80,"B",IF(CZ22>=70,"C",IF(CZ22>=60,"D",IF(CZ22>0,"F"," "))))) | DE22: =IF(A22="","",DA22-ROW()/100000000)
B23: =IF(COUNTA(C3,D3,E3,F3,G3,H3,I3,J3,K3,L3,M3,N3,O3,P3,Q3)=0,"",COUNTA(C3,D3,E3,F3,G3,H3,I3,J3,K3,L3,M3,N3,O3,P3,Q3)) | R23: =IFERROR(SUM(C23,D23,E23,F23,G23,H23,I23,J23,K23,L23,M23,N23,O23,P23,Q23)/B23*30,0) -> 0 | S23: =IF(COUNTA(T3,U3,V3,W3,X3,Y3,Z3,AA3,AB3,AC3,AD3,AE3,AF3,AG3,AH3)=0,"",COUNTA(T3,U3,V3,W3,X3,Y3,Z3,AA3,AB3,AC3,AD3,AE3,AF3,AG3,AH3)) | AI23: =IFERROR(SUM(T23,U23,V23,W23,X23,Y23,Z23,AA23,AB23,AC23,AD23,AE23,AF23,AG23,AH23)/S23*30,0) -> 0 | AJ23: =IF(COUNTA(AK3,AN3,AQ3,AT3,AW3,AZ3,BC3,BF3,BI3,BL3,BO3,BR3,BU3,BX3,CA3,CD3,CG3,CJ3,CM3,CP3)=0,"",COUNTA(AK3,AN3,AQ3,AT3,AW3,AZ3,BC3,BF3,BI3,BL3,BO3,BR3,BU3,BX3,CA3,CD3,CG3,CJ3,CM3,CP3)) | CS23: =IFERROR(SUM(AK23,AN23,AQ23,AT23,AW23,AZ23,BC23,BF23,BI23,BL23,BO23,BR23,BU23,BX23,CA23,CD23,CG23,CJ23,CM23,CP23)/AJ23*10,0) -> 0 | CT23: =IFERROR(SUM(AL23,AO23,AR23,AU23,AX23,BA23,BD23,BG23,BJ23,BM23,BP23,BS23,BV23,BY23,CB23,CE23,CH23,CK23,CN23,CQ23)/AJ23/5*5,0) -> 0 | CU23: =IFERROR(SUM(AM23,AP23,AS23,AV23,AY23,BB23,BE23,BH23,BK23,BN23,BQ23,BT23,BW23,BZ23,CC23,CF23,CI23,CL23,CO23,CR23)/AJ23*5,0) -> 0 | CV23: =ROUND(SUM(CS23,CT23,CU23),2) -> 0 | CZ23: =ROUND(SUM(R23,AI23,CV23,CW23,CX23,CY23),2) -> 0 | DA23: =ROUND(CZ23/110*100,1) -> 0 | DB23: =IF(CZ23>=90,"A",IF(CZ23>=80,"B",IF(CZ23>=70,"C",IF(CZ23>=60,"D",IF(CZ23>0,"F"," "))))) | DE23: =IF(A23="","",DA23-ROW()/100000000)
B24: =IF(COUNTA(C3,D3,E3,F3,G3,H3,I3,J3,K3,L3,M3,N3,O3,P3,Q3)=0,"",COUNTA(C3,D3,E3,F3,G3,H3,I3,J3,K3,L3,M3,N3,O3,P3,Q3)) | R24: =IFERROR(SUM(C24,D24,E24,F24,G24,H24,I24,J24,K24,L24,M24,N24,O24,P24,Q24)/B24*30,0) -> 0 | S24: =IF(COUNTA(T3,U3,V3,W3,X3,Y3,Z3,AA3,AB3,AC3,AD3,AE3,AF3,AG3,AH3)=0,"",COUNTA(T3,U3,V3,W3,X3,Y3,Z3,AA3,AB3,AC3,AD3,AE3,AF3,AG3,AH3)) | AI24: =IFERROR(SUM(T24,U24,V24,W24,X24,Y24,Z24,AA24,AB24,AC24,AD24,AE24,AF24,AG24,AH24)/S24*30,0) -> 0 | AJ24: =IF(COUNTA(AK3,AN3,AQ3,AT3,AW3,AZ3,BC3,BF3,BI3,BL3,BO3,BR3,BU3,BX3,CA3,CD3,CG3,CJ3,CM3,CP3)=0,"",COUNTA(AK3,AN3,AQ3,AT3,AW3,AZ3,BC3,BF3,BI3,BL3,BO3,BR3,BU3,BX3,CA3,CD3,CG3,CJ3,CM3,CP3)) | CS24: =IFERROR(SUM(AK24,AN24,AQ24,AT24,AW24,AZ24,BC24,BF24,BI24,BL24,BO24,BR24,BU24,BX24,CA24,CD24,CG24,CJ24,CM24,CP24)/AJ24*10,0) -> 0 | CT24: =IFERROR(SUM(AL24,AO24,AR24,AU24,AX24,BA24,BD24,BG24,BJ24,BM24,BP24,BS24,BV24,BY24,CB24,CE24,CH24,CK24,CN24,CQ24)/AJ24/5*5,0) -> 0 | CU24: =IFERROR(SUM(AM24,AP24,AS24,AV24,AY24,BB24,BE24,BH24,BK24,BN24,BQ24,BT24,BW24,BZ24,CC24,CF24,CI24,CL24,CO24,CR24)/AJ24*5,0) -> 0 | CV24: =ROUND(SUM(CS24,CT24,CU24),2) -> 0 | CZ24: =ROUND(SUM(R24,AI24,CV24,CW24,CX24,CY24),2) -> 0 | DA24: =ROUND(CZ24/110*100,1) -> 0 | DB24: =IF(CZ24>=90,"A",IF(CZ24>=80,"B",IF(CZ24>=70,"C",IF(CZ24>=60,"D",IF(CZ24>0,"F"," "))))) | DE24: =IF(A24="","",DA24-ROW()/100000000)
B25: =IF(COUNTA(C3,D3,E3,F3,G3,H3,I3,J3,K3,L3,M3,N3,O3,P3,Q3)=0,"",COUNTA(C3,D3,E3,F3,G3,H3,I3,J3,K3,L3,M3,N3,O3,P3,Q3)) | R25: =IFERROR(SUM(C25,D25,E25,F25,G25,H25,I25,J25,K25,L25,M25,N25,O25,P25,Q25)/B25*30,0) -> 0 | S25: =IF(COUNTA(T3,U3,V3,W3,X3,Y3,Z3,AA3,AB3,AC3,AD3,AE3,AF3,AG3,AH3)=0,"",COUNTA(T3,U3,V3,W3,X3,Y3,Z3,AA3,AB3,AC3,AD3,AE3,AF3,AG3,AH3)) | AI25: =IFERROR(SUM(T25,U25,V25,W25,X25,Y25,Z25,AA25,AB25,AC25,AD25,AE25,AF25,AG25,AH25)/S25*30,0) -> 0 | AJ25: =IF(COUNTA(AK3,AN3,AQ3,AT3,AW3,AZ3,BC3,BF3,BI3,BL3,BO3,BR3,BU3,BX3,CA3,CD3,CG3,CJ3,CM3,CP3)=0,"",COUNTA(AK3,AN3,AQ3,AT3,AW3,AZ3,BC3,BF3,BI3,BL3,BO3,BR3,BU3,BX3,CA3,CD3,CG3,CJ3,CM3,CP3)) | CS25: =IFERROR(SUM(AK25,AN25,AQ25,AT25,AW25,AZ25,BC25,BF25,BI25,BL25,BO25,BR25,BU25,BX25,CA25,CD25,CG25,CJ25,CM25,CP25)/AJ25*10,0) -> 0 | CT25: =IFERROR(SUM(AL25,AO25,AR25,AU25,AX25,BA25,BD25,BG25,BJ25,BM25,BP25,BS25,BV25,BY25,CB25,CE25,CH25,CK25,CN25,CQ25)/AJ25/5*5,0) -> 0 | CU25: =IFERROR(SUM(AM25,AP25,AS25,AV25,AY25,BB25,BE25,BH25,BK25,BN25,BQ25,BT25,BW25,BZ25,CC25,CF25,CI25,CL25,CO25,CR25)/AJ25*5,0) -> 0 | CV25: =ROUND(SUM(CS25,CT25,CU25),2) -> 0 | CZ25: =ROUND(SUM(R25,AI25,CV25,CW25,CX25,CY25),2) -> 0 | DA25: =ROUND(CZ25/110*100,1) -> 0 | DB25: =IF(CZ25>=90,"A",IF(CZ25>=80,"B",IF(CZ25>=70,"C",IF(CZ25>=60,"D",IF(CZ25>0,"F"," "))))) | DE25: =IF(A25="","",DA25-ROW()/100000000)
B26: =IF(COUNTA(C3,D3,E3,F3,G3,H3,I3,J3,K3,L3,M3,N3,O3,P3,Q3)=0,"",COUNTA(C3,D3,E3,F3,G3,H3,I3,J3,K3,L3,M3,N3,O3,P3,Q3)) | R26: =IFERROR(SUM(C26,D26,E26,F26,G26,H26,I26,J26,K26,L26,M26,N26,O26,P26,Q26)/B26*30,0) -> 0 | S26: =IF(COUNTA(T3,U3,V3,W3,X3,Y3,Z3,AA3,AB3,AC3,AD3,AE3,AF3,AG3,AH3)=0,"",COUNTA(T3,U3,V3,W3,X3,Y3,Z3,AA3,AB3,AC3,AD3,AE3,AF3,AG3,AH3)) | AI26: =IFERROR(SUM(T26,U26,V26,W26,X26,Y26,Z26,AA26,AB26,AC26,AD26,AE26,AF26,AG26,AH26)/S26*30,0) -> 0 | AJ26: =IF(COUNTA(AK3,AN3,AQ3,AT3,AW3,AZ3,BC3,BF3,BI3,BL3,BO3,BR3,BU3,BX3,CA3,CD3,CG3,CJ3,CM3,CP3)=0,"",COUNTA(AK3,AN3,AQ3,AT3,AW3,AZ3,BC3,BF3,BI3,BL3,BO3,BR3,BU3,BX3,CA3,CD3,CG3,CJ3,CM3,CP3)) | CS26: =IFERROR(SUM(AK26,AN26,AQ26,AT26,AW26,AZ26,BC26,BF26,BI26,BL26,BO26,BR26,BU26,BX26,CA26,CD26,CG26,CJ26,CM26,CP26)/AJ26*10,0) -> 0 | CT26: =IFERROR(SUM(AL26,AO26,AR26,AU26,AX26,BA26,BD26,BG26,BJ26,BM26,BP26,BS26,BV26,BY26,CB26,CE26,CH26,CK26,CN26,CQ26)/AJ26/5*5,0) -> 0 | CU26: =IFERROR(SUM(AM26,AP26,AS26,AV26,AY26,BB26,BE26,BH26,BK26,BN26,BQ26,BT26,BW26,BZ26,CC26,CF26,CI26,CL26,CO26,CR26)/AJ26*5,0) -> 0 | CV26: =ROUND(SUM(CS26,CT26,CU26),2) -> 0 | CZ26: =ROUND(SUM(R26,AI26,CV26,CW26,CX26,CY26),2) -> 0 | DA26: =ROUND(CZ26/110*100,1) -> 0 | DB26: =IF(CZ26>=90,"A",IF(CZ26>=80,"B",IF(CZ26>=70,"C",IF(CZ26>=60,"D",IF(CZ26>0,"F"," "))))) | DE26: =IF(A26="","",DA26-ROW()/100000000)
B27: =IF(COUNTA(C3,D3,E3,F3,G3,H3,I3,J3,K3,L3,M3,N3,O3,P3,Q3)=0,"",COUNTA(C3,D3,E3,F3,G3,H3,I3,J3,K3,L3,M3,N3,O3,P3,Q3)) | R27: =IFERROR(SUM(C27,D27,E27,F27,G27,H27,I27,J27,K27,L27,M27,N27,O27,P27,Q27)/B27*30,0) -> 0 | S27: =IF(COUNTA(T3,U3,V3,W3,X3,Y3,Z3,AA3,AB3,AC3,AD3,AE3,AF3,AG3,AH3)=0,"",COUNTA(T3,U3,V3,W3,X3,Y3,Z3,AA3,AB3,AC3,AD3,AE3,AF3,AG3,AH3)) | AI27: =IFERROR(SUM(T27,U27,V27,W27,X27,Y27,Z27,AA27,AB27,AC27,AD27,AE27,AF27,AG27,AH27)/S27*30,0) -> 0 | AJ27: =IF(COUNTA(AK3,AN3,AQ3,AT3,AW3,AZ3,BC3,BF3,BI3,BL3,BO3,BR3,BU3,BX3,CA3,CD3,CG3,CJ3,CM3,CP3)=0,"",COUNTA(AK3,AN3,AQ3,AT3,AW3,AZ3,BC3,BF3,BI3,BL3,BO3,BR3,BU3,BX3,CA3,CD3,CG3,CJ3,CM3,CP3)) | CS27: =IFERROR(SUM(AK27,AN27,AQ27,AT27,AW27,AZ27,BC27,BF27,BI27,BL27,BO27,BR27,BU27,BX27,CA27,CD27,CG27,CJ27,CM27,CP27)/AJ27*10,0) -> 0 | CT27: =IFERROR(SUM(AL27,AO27,AR27,AU27,AX27,BA27,BD27,BG27,BJ27,BM27,BP27,BS27,BV27,BY27,CB27,CE27,CH27,CK27,CN27,CQ27)/AJ27/5*5,0) -> 0 | CU27: =IFERROR(SUM(AM27,AP27,AS27,AV27,AY27,BB27,BE27,BH27,BK27,BN27,BQ27,BT27,BW27,BZ27,CC27,CF27,CI27,CL27,CO27,CR27)/AJ27*5,0) -> 0 | CV27: =ROUND(SUM(CS27,CT27,CU27),2) -> 0 | CZ27: =ROUND(SUM(R27,AI27,CV27,CW27,CX27,CY27),2) -> 0 | DA27: =ROUND(CZ27/110*100,1) -> 0 | DB27: =IF(CZ27>=90,"A",IF(CZ27>=80,"B",IF(CZ27>=70,"C",IF(CZ27>=60,"D",IF(CZ27>0,"F"," "))))) | DE27: =IF(A27="","",DA27-ROW()/100000000)
B28: =IF(COUNTA(C3,D3,E3,F3,G3,H3,I3,J3,K3,L3,M3,N3,O3,P3,Q3)=0,"",COUNTA(C3,D3,E3,F3,G3,H3,I3,J3,K3,L3,M3,N3,O3,P3,Q3)) | R28: =IFERROR(SUM(C28,D28,E28,F28,G28,H28,I28,J28,K28,L28,M28,N28,O28,P28,Q28)/B28*30,0) -> 0 | S28: =IF(COUNTA(T3,U3,V3,W3,X3,Y3,Z3,AA3,AB3,AC3,AD3,AE3,AF3,AG3,AH3)=0,"",COUNTA(T3,U3,V3,W3,X3,Y3,Z3,AA3,AB3,AC3,AD3,AE3,AF3,AG3,AH3)) | AI28: =IFERROR(SUM(T28,U28,V28,W28,X28,Y28,Z28,AA28,AB28,AC28,AD28,AE28,AF28,AG28,AH28)/S28*30,0) -> 0 | AJ28: =IF(COUNTA(AK3,AN3,AQ3,AT3,AW3,AZ3,BC3,BF3,BI3,BL3,BO3,BR3,BU3,BX3,CA3,CD3,CG3,CJ3,CM3,CP3)=0,"",COUNTA(AK3,AN3,AQ3,AT3,AW3,AZ3,BC3,BF3,BI3,BL3,BO3,BR3,BU3,BX3,CA3,CD3,CG3,CJ3,CM3,CP3)) | CS28: =IFERROR(SUM(AK28,AN28,AQ28,AT28,AW28,AZ28,BC28,BF28,BI28,BL28,BO28,BR28,BU28,BX28,CA28,CD28,CG28,CJ28,CM28,CP28)/AJ28*10,0) -> 0 | CT28: =IFERROR(SUM(AL28,AO28,AR28,AU28,AX28,BA28,BD28,BG28,BJ28,BM28,BP28,BS28,BV28,BY28,CB28,CE28,CH28,CK28,CN28,CQ28)/AJ28/5*5,0) -> 0 | CU28: =IFERROR(SUM(AM28,AP28,AS28,AV28,AY28,BB28,BE28,BH28,BK28,BN28,BQ28,BT28,BW28,BZ28,CC28,CF28,CI28,CL28,CO28,CR28)/AJ28*5,0) -> 0 | CV28: =ROUND(SUM(CS28,CT28,CU28),2) -> 0 | CZ28: =ROUND(SUM(R28,AI28,CV28,CW28,CX28,CY28),2) -> 0 | DA28: =ROUND(CZ28/110*100,1) -> 0 | DB28: =IF(CZ28>=90,"A",IF(CZ28>=80,"B",IF(CZ28>=70,"C",IF(CZ28>=60,"D",IF(CZ28>0,"F"," "))))) | DE28: =IF(A28="","",DA28-ROW()/100000000)
B29: =IF(COUNTA(C3,D3,E3,F3,G3,H3,I3,J3,K3,L3,M3,N3,O3,P3,Q3)=0,"",COUNTA(C3,D3,E3,F3,G3,H3,I3,J3,K3,L3,M3,N3,O3,P3,Q3)) | R29: =IFERROR(SUM(C29,D29,E29,F29,G29,H29,I29,J29,K29,L29,M29,N29,O29,P29,Q29)/B29*30,0) -> 0 | S29: =IF(COUNTA(T3,U3,V3,W3,X3,Y3,Z3,AA3,AB3,AC3,AD3,AE3,AF3,AG3,AH3)=0,"",COUNTA(T3,U3,V3,W3,X3,Y3,Z3,AA3,AB3,AC3,AD3,AE3,AF3,AG3,AH3)) | AI29: =IFERROR(SUM(T29,U29,V29,W29,X29,Y29,Z29,AA29,AB29,AC29,AD29,AE29,AF29,AG29,AH29)/S29*30,0) -> 0 | AJ29: =IF(COUNTA(AK3,AN3,AQ3,AT3,AW3,AZ3,BC3,BF3,BI3,BL3,BO3,BR3,BU3,BX3,CA3,CD3,CG3,CJ3,CM3,CP3)=0,"",COUNTA(AK3,AN3,AQ3,AT3,AW3,AZ3,BC3,BF3,BI3,BL3,BO3,BR3,BU3,BX3,CA3,CD3,CG3,CJ3,CM3,CP3)) | CS29: =IFERROR(SUM(AK29,AN29,AQ29,AT29,AW29,AZ29,BC29,BF29,BI29,BL29,BO29,BR29,BU29,BX29,CA29,CD29,CG29,CJ29,CM29,CP29)/AJ29*10,0) -> 0 | CT29: =IFERROR(SUM(AL29,AO29,AR29,AU29,AX29,BA29,BD29,BG29,BJ29,BM29,BP29,BS29,BV29,BY29,CB29,CE29,CH29,CK29,CN29,CQ29)/AJ29/5*5,0) -> 0 | CU29: =IFERROR(SUM(AM29,AP29,AS29,AV29,AY29,BB29,BE29,BH29,BK29,BN29,BQ29,BT29,BW29,BZ29,CC29,CF29,CI29,CL29,CO29,CR29)/AJ29*5,0) -> 0 | CV29: =ROUND(SUM(CS29,CT29,CU29),2) -> 0 | CZ29: =ROUND(SUM(R29,AI29,CV29,CW29,CX29,CY29),2) -> 0 | DA29: =ROUND(CZ29/110*100,1) -> 0 | DB29: =IF(CZ29>=90,"A",IF(CZ29>=80,"B",IF(CZ29>=70,"C",IF(CZ29>=60,"D",IF(CZ29>0,"F"," "))))) | DE29: =IF(A29="","",DA29-ROW()/100000000)
B30: =IF(COUNTA(C3,D3,E3,F3,G3,H3,I3,J3,K3,L3,M3,N3,O3,P3,Q3)=0,"",COUNTA(C3,D3,E3,F3,G3,H3,I3,J3,K3,L3,M3,N3,O3,P3,Q3)) | R30: =IFERROR(SUM(C30,D30,E30,F30,G30,H30,I30,J30,K30,L30,M30,N30,O30,P30,Q30)/B30*30,0) -> 0 | S30: =IF(COUNTA(T3,U3,V3,W3,X3,Y3,Z3,AA3,AB3,AC3,AD3,AE3,AF3,AG3,AH3)=0,"",COUNTA(T3,U3,V3,W3,X3,Y3,Z3,AA3,AB3,AC3,AD3,AE3,AF3,AG3,AH3)) | AI30: =IFERROR(SUM(T30,U30,V30,W30,X30,Y30,Z30,AA30,AB30,AC30,AD30,AE30,AF30,AG30,AH30)/S30*30,0) -> 0 | AJ30: =IF(COUNTA(AK3,AN3,AQ3,AT3,AW3,AZ3,BC3,BF3,BI3,BL3,BO3,BR3,BU3,BX3,CA3,CD3,CG3,CJ3,CM3,CP3)=0,"",COUNTA(AK3,AN3,AQ3,AT3,AW3,AZ3,BC3,BF3,BI3,BL3,BO3,BR3,BU3,BX3,CA3,CD3,CG3,CJ3,CM3,CP3)) | CS30: =IFERROR(SUM(AK30,AN30,AQ30,AT30,AW30,AZ30,BC30,BF30,BI30,BL30,BO30,BR30,BU30,BX30,CA30,CD30,CG30,CJ30,CM30,CP30)/AJ30*10,0) -> 0 | CT30: =IFERROR(SUM(AL30,AO30,AR30,AU30,AX30,BA30,BD30,BG30,BJ30,BM30,BP30,BS30,BV30,BY30,CB30,CE30,CH30,CK30,CN30,CQ30)/AJ30/5*5,0) -> 0 | CU30: =IFERROR(SUM(AM30,AP30,AS30,AV30,AY30,BB30,BE30,BH30,BK30,BN30,BQ30,BT30,BW30,BZ30,CC30,CF30,CI30,CL30,CO30,CR30)/AJ30*5,0) -> 0 | CV30: =ROUND(SUM(CS30,CT30,CU30),2) -> 0 | CZ30: =ROUND(SUM(R30,AI30,CV30,CW30,CX30,CY30),2) -> 0 | DA30: =ROUND(CZ30/110*100,1) -> 0 | DB30: =IF(CZ30>=90,"A",IF(CZ30>=80,"B",IF(CZ30>=70,"C",IF(CZ30>=60,"D",IF(CZ30>0,"F"," "))))) | DE30: =IF(A30="","",DA30-ROW()/100000000)
B31: =IF(COUNTA(C3,D3,E3,F3,G3,H3,I3,J3,K3,L3,M3,N3,O3,P3,Q3)=0,"",COUNTA(C3,D3,E3,F3,G3,H3,I3,J3,K3,L3,M3,N3,O3,P3,Q3)) | R31: =IFERROR(SUM(C31,D31,E31,F31,G31,H31,I31,J31,K31,L31,M31,N31,O31,P31,Q31)/B31*30,0) -> 0 | S31: =IF(COUNTA(T3,U3,V3,W3,X3,Y3,Z3,AA3,AB3,AC3,AD3,AE3,AF3,AG3,AH3)=0,"",COUNTA(T3,U3,V3,W3,X3,Y3,Z3,AA3,AB3,AC3,AD3,AE3,AF3,AG3,AH3)) | AI31: =IFERROR(SUM(T31,U31,V31,W31,X31,Y31,Z31,AA31,AB31,AC31,AD31,AE31,AF31,AG31,AH31)/S31*30,0) -> 0 | AJ31: =IF(COUNTA(AK3,AN3,AQ3,AT3,AW3,AZ3,BC3,BF3,BI3,BL3,BO3,BR3,BU3,BX3,CA3,CD3,CG3,CJ3,CM3,CP3)=0,"",COUNTA(AK3,AN3,AQ3,AT3,AW3,AZ3,BC3,BF3,BI3,BL3,BO3,BR3,BU3,BX3,CA3,CD3,CG3,CJ3,CM3,CP3)) | CS31: =IFERROR(SUM(AK31,AN31,AQ31,AT31,AW31,AZ31,BC31,BF31,BI31,BL31,BO31,BR31,BU31,BX31,CA31,CD31,CG31,CJ31,CM31,CP31)/AJ31*10,0) -> 0 | CT31: =IFERROR(SUM(AL31,AO31,AR31,AU31,AX31,BA31,BD31,BG31,BJ31,BM31,BP31,BS31,BV31,BY31,CB31,CE31,CH31,CK31,CN31,CQ31)/AJ31/5*5,0) -> 0 | CU31: =IFERROR(SUM(AM31,AP31,AS31,AV31,AY31,BB31,BE31,BH31,BK31,BN31,BQ31,BT31,BW31,BZ31,CC31,CF31,CI31,CL31,CO31,CR31)/AJ31*5,0) -> 0 | CV31: =ROUND(SUM(CS31,CT31,CU31),2) -> 0 | CZ31: =ROUND(SUM(R31,AI31,CV31,CW31,CX31,CY31),2) -> 0 | DA31: =ROUND(CZ31/110*100,1) -> 0 | DB31: =IF(CZ31>=90,"A",IF(CZ31>=80,"B",IF(CZ31>=70,"C",IF(CZ31>=60,"D",IF(CZ31>0,"F"," "))))) | DE31: =IF(A31="","",DA31-ROW()/100000000)
B32: =IF(COUNTA(C3,D3,E3,F3,G3,H3,I3,J3,K3,L3,M3,N3,O3,P3,Q3)=0,"",COUNTA(C3,D3,E3,F3,G3,H3,I3,J3,K3,L3,M3,N3,O3,P3,Q3)) | R32: =IFERROR(SUM(C32,D32,E32,F32,G32,H32,I32,J32,K32,L32,M32,N32,O32,P32,Q32)/B32*30,0) -> 0 | S32: =IF(COUNTA(T3,U3,V3,W3,X3,Y3,Z3,AA3,AB3,AC3,AD3,AE3,AF3,AG3,AH3)=0,"",COUNTA(T3,U3,V3,W3,X3,Y3,Z3,AA3,AB3,AC3,AD3,AE3,AF3,AG3,AH3)) | AI32: =IFERROR(SUM(T32,U32,V32,W32,X32,Y32,Z32,AA32,AB32,AC32,AD32,AE32,AF32,AG32,AH32)/S32*30,0) -> 0 | AJ32: =IF(COUNTA(AK3,AN3,AQ3,AT3,AW3,AZ3,BC3,BF3,BI3,BL3,BO3,BR3,BU3,BX3,CA3,CD3,CG3,CJ3,CM3,CP3)=0,"",COUNTA(AK3,AN3,AQ3,AT3,AW3,AZ3,BC3,BF3,BI3,BL3,BO3,BR3,BU3,BX3,CA3,CD3,CG3,CJ3,CM3,CP3)) | CS32: =IFERROR(SUM(AK32,AN32,AQ32,AT32,AW32,AZ32,BC32,BF32,BI32,BL32,BO32,BR32,BU32,BX32,CA32,CD32,CG32,CJ32,CM32,CP32)/AJ32*10,0) -> 0 | CT32: =IFERROR(SUM(AL32,AO32,AR32,AU32,AX32,BA32,BD32,BG32,BJ32,BM32,BP32,BS32,BV32,BY32,CB32,CE32,CH32,CK32,CN32,CQ32)/AJ32/5*5,0) -> 0 | CU32: =IFERROR(SUM(AM32,AP32,AS32,AV32,AY32,BB32,BE32,BH32,BK32,BN32,BQ32,BT32,BW32,BZ32,CC32,CF32,CI32,CL32,CO32,CR32)/AJ32*5,0) -> 0 | CV32: =ROUND(SUM(CS32,CT32,CU32),2) -> 0 | CZ32: =ROUND(SUM(R32,AI32,CV32,CW32,CX32,CY32),2) -> 0 | DA32: =ROUND(CZ32/110*100,1) -> 0 | DB32: =IF(CZ32>=90,"A",IF(CZ32>=80,"B",IF(CZ32>=70,"C",IF(CZ32>=60,"D",IF(CZ32>0,"F"," "))))) | DE32: =IF(A32="","",DA32-ROW()/100000000)
B33: =IF(COUNTA(C3,D3,E3,F3,G3,H3,I3,J3,K3,L3,M3,N3,O3,P3,Q3)=0,"",COUNTA(C3,D3,E3,F3,G3,H3,I3,J3,K3,L3,M3,N3,O3,P3,Q3)) | R33: =IFERROR(SUM(C33,D33,E33,F33,G33,H33,I33,J33,K33,L33,M33,N33,O33,P33,Q33)/B33*30,0) -> 0 | S33: =IF(COUNTA(T3,U3,V3,W3,X3,Y3,Z3,AA3,AB3,AC3,AD3,AE3,AF3,AG3,AH3)=0,"",COUNTA(T3,U3,V3,W3,X3,Y3,Z3,AA3,AB3,AC3,AD3,AE3,AF3,AG3,AH3)) | AI33: =IFERROR(SUM(T33,U33,V33,W33,X33,Y33,Z33,AA33,AB33,AC33,AD33,AE33,AF33,AG33,AH33)/S33*30,0) -> 0 | AJ33: =IF(COUNTA(AK3,AN3,AQ3,AT3,AW3,AZ3,BC3,BF3,BI3,BL3,BO3,BR3,BU3,BX3,CA3,CD3,CG3,CJ3,CM3,CP3)=0,"",COUNTA(AK3,AN3,AQ3,AT3,AW3,AZ3,BC3,BF3,BI3,BL3,BO3,BR3,BU3,BX3,CA3,CD3,CG3,CJ3,CM3,CP3)) | CS33: =IFERROR(SUM(AK33,AN33,AQ33,AT33,AW33,AZ33,BC33,BF33,BI33,BL33,BO33,BR33,BU33,BX33,CA33,CD33,CG33,CJ33,CM33,CP33)/AJ33*10,0) -> 0 | CT33: =IFERROR(SUM(AL33,AO33,AR33,AU33,AX33,BA33,BD33,BG33,BJ33,BM33,BP33,BS33,BV33,BY33,CB33,CE33,CH33,CK33,CN33,CQ33)/AJ33/5*5,0) -> 0 | CU33: =IFERROR(SUM(AM33,AP33,AS33,AV33,AY33,BB33,BE33,BH33,BK33,BN33,BQ33,BT33,BW33,BZ33,CC33,CF33,CI33,CL33,CO33,CR33)/AJ33*5,0) -> 0 | CV33: =ROUND(SUM(CS33,CT33,CU33),2) -> 0 | CZ33: =ROUND(SUM(R33,AI33,CV33,CW33,CX33,CY33),2) -> 0 | DA33: =ROUND(CZ33/110*100,1) -> 0 | DB33: =IF(CZ33>=90,"A",IF(CZ33>=80,"B",IF(CZ33>=70,"C",IF(CZ33>=60,"D",IF(CZ33>0,"F"," "))))) | DE33: =IF(A33="","",DA33-ROW()/100000000)
B34: =IF(COUNTA(C3,D3,E3,F3,G3,H3,I3,J3,K3,L3,M3,N3,O3,P3,Q3)=0,"",COUNTA(C3,D3,E3,F3,G3,H3,I3,J3,K3,L3,M3,N3,O3,P3,Q3)) | R34: =IFERROR(SUM(C34,D34,E34,F34,G34,H34,I34,J34,K34,L34,M34,N34,O34,P34,Q34)/B34*30,0) -> 0 | S34: =IF(COUNTA(T3,U3,V3,W3,X3,Y3,Z3,AA3,AB3,AC3,AD3,AE3,AF3,AG3,AH3)=0,"",COUNTA(T3,U3,V3,W3,X3,Y3,Z3,AA3,AB3,AC3,AD3,AE3,AF3,AG3,AH3)) | AI34: =IFERROR(SUM(T34,U34,V34,W34,X34,Y34,Z34,AA34,AB34,AC34,AD34,AE34,AF34,AG34,AH34)/S34*30,0) -> 0 | AJ34: =IF(COUNTA(AK3,AN3,AQ3,AT3,AW3,AZ3,BC3,BF3,BI3,BL3,BO3,BR3,BU3,BX3,CA3,CD3,CG3,CJ3,CM3,CP3)=0,"",COUNTA(AK3,AN3,AQ3,AT3,AW3,AZ3,BC3,BF3,BI3,BL3,BO3,BR3,BU3,BX3,CA3,CD3,CG3,CJ3,CM3,CP3)) | CS34: =IFERROR(SUM(AK34,AN34,AQ34,AT34,AW34,AZ34,BC34,BF34,BI34,BL34,BO34,BR34,BU34,BX34,CA34,CD34,CG34,CJ34,CM34,CP34)/AJ34*10,0) -> 0 | CT34: =IFERROR(SUM(AL34,AO34,AR34,AU34,AX34,BA34,BD34,BG34,BJ34,BM34,BP34,BS34,BV34,BY34,CB34,CE34,CH34,CK34,CN34,CQ34)/AJ34/5*5,0) -> 0 | CU34: =IFERROR(SUM(AM34,AP34,AS34,AV34,AY34,BB34,BE34,BH34,BK34,BN34,BQ34,BT34,BW34,BZ34,CC34,CF34,CI34,CL34,CO34,CR34)/AJ34*5,0) -> 0 | CV34: =ROUND(SUM(CS34,CT34,CU34),2) -> 0 | CZ34: =ROUND(SUM(R34,AI34,CV34,CW34,CX34,CY34),2) -> 0 | DA34: =ROUND(CZ34/110*100,1) -> 0 | DB34: =IF(CZ34>=90,"A",IF(CZ34>=80,"B",IF(CZ34>=70,"C",IF(CZ34>=60,"D",IF(CZ34>0,"F"," "))))) | DE34: =IF(A34="","",DA34-ROW()/100000000)
B35: =IF(COUNTA(C3,D3,E3,F3,G3,H3,I3,J3,K3,L3,M3,N3,O3,P3,Q3)=0,"",COUNTA(C3,D3,E3,F3,G3,H3,I3,J3,K3,L3,M3,N3,O3,P3,Q3)) | R35: =IFERROR(SUM(C35,D35,E35,F35,G35,H35,I35,J35,K35,L35,M35,N35,O35,P35,Q35)/B35*30,0) -> 0 | S35: =IF(COUNTA(T3,U3,V3,W3,X3,Y3,Z3,AA3,AB3,AC3,AD3,AE3,AF3,AG3,AH3)=0,"",COUNTA(T3,U3,V3,W3,X3,Y3,Z3,AA3,AB3,AC3,AD3,AE3,AF3,AG3,AH3)) | AI35: =IFERROR(SUM(T35,U35,V35,W35,X35,Y35,Z35,AA35,AB35,AC35,AD35,AE35,AF35,AG35,AH35)/S35*30,0) -> 0 | AJ35: =IF(COUNTA(AK3,AN3,AQ3,AT3,AW3,AZ3,BC3,BF3,BI3,BL3,BO3,BR3,BU3,BX3,CA3,CD3,CG3,CJ3,CM3,CP3)=0,"",COUNTA(AK3,AN3,AQ3,AT3,AW3,AZ3,BC3,BF3,BI3,BL3,BO3,BR3,BU3,BX3,CA3,CD3,CG3,CJ3,CM3,CP3)) | CS35: =IFERROR(SUM(AK35,AN35,AQ35,AT35,AW35,AZ35,BC35,BF35,BI35,BL35,BO35,BR35,BU35,BX35,CA35,CD35,CG35,CJ35,CM35,CP35)/AJ35*10,0) -> 0 | CT35: =IFERROR(SUM(AL35,AO35,AR35,AU35,AX35,BA35,BD35,BG35,BJ35,BM35,BP35,BS35,BV35,BY35,CB35,CE35,CH35,CK35,CN35,CQ35)/AJ35/5*5,0) -> 0 | CU35: =IFERROR(SUM(AM35,AP35,AS35,AV35,AY35,BB35,BE35,BH35,BK35,BN35,BQ35,BT35,BW35,BZ35,CC35,CF35,CI35,CL35,CO35,CR35)/AJ35*5,0) -> 0 | CV35: =ROUND(SUM(CS35,CT35,CU35),2) -> 0 | CZ35: =ROUND(SUM(R35,AI35,CV35,CW35,CX35,CY35),2) -> 0 | DA35: =ROUND(CZ35/110*100,1) -> 0 | DB35: =IF(CZ35>=90,"A",IF(CZ35>=80,"B",IF(CZ35>=70,"C",IF(CZ35>=60,"D",IF(CZ35>0,"F"," "))))) | DE35: =IF(A35="","",DA35-ROW()/100000000)
B36: =IF(COUNTA(C3,D3,E3,F3,G3,H3,I3,J3,K3,L3,M3,N3,O3,P3,Q3)=0,"",COUNTA(C3,D3,E3,F3,G3,H3,I3,J3,K3,L3,M3,N3,O3,P3,Q3)) | R36: =IFERROR(SUM(C36,D36,E36,F36,G36,H36,I36,J36,K36,L36,M36,N36,O36,P36,Q36)/B36*30,0) -> 0 | S36: =IF(COUNTA(T3,U3,V3,W3,X3,Y3,Z3,AA3,AB3,AC3,AD3,AE3,AF3,AG3,AH3)=0,"",COUNTA(T3,U3,V3,W3,X3,Y3,Z3,AA3,AB3,AC3,AD3,AE3,AF3,AG3,AH3)) | AI36: =IFERROR(SUM(T36,U36,V36,W36,X36,Y36,Z36,AA36,AB36,AC36,AD36,AE36,AF36,AG36,AH36)/S36*30,0) -> 0 | AJ36: =IF(COUNTA(AK3,AN3,AQ3,AT3,AW3,AZ3,BC3,BF3,BI3,BL3,BO3,BR3,BU3,BX3,CA3,CD3,CG3,CJ3,CM3,CP3)=0,"",COUNTA(AK3,AN3,AQ3,AT3,AW3,AZ3,BC3,BF3,BI3,BL3,BO3,BR3,BU3,BX3,CA3,CD3,CG3,CJ3,CM3,CP3)) | CS36: =IFERROR(SUM(AK36,AN36,AQ36,AT36,AW36,AZ36,BC36,BF36,BI36,BL36,BO36,BR36,BU36,BX36,CA36,CD36,CG36,CJ36,CM36,CP36)/AJ36*10,0) -> 0 | CT36: =IFERROR(SUM(AL36,AO36,AR36,AU36,AX36,BA36,BD36,BG36,BJ36,BM36,BP36,BS36,BV36,BY36,CB36,CE36,CH36,CK36,CN36,CQ36)/AJ36/5*5,0) -> 0 | CU36: =IFERROR(SUM(AM36,AP36,AS36,AV36,AY36,BB36,BE36,BH36,BK36,BN36,BQ36,BT36,BW36,BZ36,CC36,CF36,CI36,CL36,CO36,CR36)/AJ36*5,0) -> 0 | CV36: =ROUND(SUM(CS36,CT36,CU36),2) -> 0 | CZ36: =ROUND(SUM(R36,AI36,CV36,CW36,CX36,CY36),2) -> 0 | DA36: =ROUND(CZ36/110*100,1) -> 0 | DB36: =IF(CZ36>=90,"A",IF(CZ36>=80,"B",IF(CZ36>=70,"C",IF(CZ36>=60,"D",IF(CZ36>0,"F"," "))))) | DE36: =IF(A36="","",DA36-ROW()/100000000)
B37: =IF(COUNTA(C3,D3,E3,F3,G3,H3,I3,J3,K3,L3,M3,N3,O3,P3,Q3)=0,"",COUNTA(C3,D3,E3,F3,G3,H3,I3,J3,K3,L3,M3,N3,O3,P3,Q3)) | R37: =IFERROR(SUM(C37,D37,E37,F37,G37,H37,I37,J37,K37,L37,M37,N37,O37,P37,Q37)/B37*30,0) -> 0 | S37: =IF(COUNTA(T3,U3,V3,W3,X3,Y3,Z3,AA3,AB3,AC3,AD3,AE3,AF3,AG3,AH3)=0,"",COUNTA(T3,U3,V3,W3,X3,Y3,Z3,AA3,AB3,AC3,AD3,AE3,AF3,AG3,AH3)) | AI37: =IFERROR(SUM(T37,U37,V37,W37,X37,Y37,Z37,AA37,AB37,AC37,AD37,AE37,AF37,AG37,AH37)/S37*30,0) -> 0 | AJ37: =IF(COUNTA(AK3,AN3,AQ3,AT3,AW3,AZ3,BC3,BF3,BI3,BL3,BO3,BR3,BU3,BX3,CA3,CD3,CG3,CJ3,CM3,CP3)=0,"",COUNTA(AK3,AN3,AQ3,AT3,AW3,AZ3,BC3,BF3,BI3,BL3,BO3,BR3,BU3,BX3,CA3,CD3,CG3,CJ3,CM3,CP3)) | CS37: =IFERROR(SUM(AK37,AN37,AQ37,AT37,AW37,AZ37,BC37,BF37,BI37,BL37,BO37,BR37,BU37,BX37,CA37,CD37,CG37,CJ37,CM37,CP37)/AJ37*10,0) -> 0 | CT37: =IFERROR(SUM(AL37,AO37,AR37,AU37,AX37,BA37,BD37,BG37,BJ37,BM37,BP37,BS37,BV37,BY37,CB37,CE37,CH37,CK37,CN37,CQ37)/AJ37/5*5,0) -> 0 | CU37: =IFERROR(SUM(AM37,AP37,AS37,AV37,AY37,BB37,BE37,BH37,BK37,BN37,BQ37,BT37,BW37,BZ37,CC37,CF37,CI37,CL37,CO37,CR37)/AJ37*5,0) -> 0 | CV37: =ROUND(SUM(CS37,CT37,CU37),2) -> 0 | CZ37: =ROUND(SUM(R37,AI37,CV37,CW37,CX37,CY37),2) -> 0 | DA37: =ROUND(CZ37/110*100,1) -> 0 | DB37: =IF(CZ37>=90,"A",IF(CZ37>=80,"B",IF(CZ37>=70,"C",IF(CZ37>=60,"D",IF(CZ37>0,"F"," "))))) | DE37: =IF(A37="","",DA37-ROW()/100000000)
B38: =IF(COUNTA(C3,D3,E3,F3,G3,H3,I3,J3,K3,L3,M3,N3,O3,P3,Q3)=0,"",COUNTA(C3,D3,E3,F3,G3,H3,I3,J3,K3,L3,M3,N3,O3,P3,Q3)) | R38: =IFERROR(SUM(C38,D38,E38,F38,G38,H38,I38,J38,K38,L38,M38,N38,O38,P38,Q38)/B38*30,0) -> 0 | S38: =IF(COUNTA(T3,U3,V3,W3,X3,Y3,Z3,AA3,AB3,AC3,AD3,AE3,AF3,AG3,AH3)=0,"",COUNTA(T3,U3,V3,W3,X3,Y3,Z3,AA3,AB3,AC3,AD3,AE3,AF3,AG3,AH3)) | AI38: =IFERROR(SUM(T38,U38,V38,W38,X38,Y38,Z38,AA38,AB38,AC38,AD38,AE38,AF38,AG38,AH38)/S38*30,0) -> 0 | AJ38: =IF(COUNTA(AK3,AN3,AQ3,AT3,AW3,AZ3,BC3,BF3,BI3,BL3,BO3,BR3,BU3,BX3,CA3,CD3,CG3,CJ3,CM3,CP3)=0,"",COUNTA(AK3,AN3,AQ3,AT3,AW3,AZ3,BC3,BF3,BI3,BL3,BO3,BR3,BU3,BX3,CA3,CD3,CG3,CJ3,CM3,CP3)) | CS38: =IFERROR(SUM(AK38,AN38,AQ38,AT38,AW38,AZ38,BC38,BF38,BI38,BL38,BO38,BR38,BU38,BX38,CA38,CD38,CG38,CJ38,CM38,CP38)/AJ38*10,0) -> 0 | CT38: =IFERROR(SUM(AL38,AO38,AR38,AU38,AX38,BA38,BD38,BG38,BJ38,BM38,BP38,BS38,BV38,BY38,CB38,CE38,CH38,CK38,CN38,CQ38)/AJ38/5*5,0) -> 0 | CU38: =IFERROR(SUM(AM38,AP38,AS38,AV38,AY38,BB38,BE38,BH38,BK38,BN38,BQ38,BT38,BW38,BZ38,CC38,CF38,CI38,CL38,CO38,CR38)/AJ38*5,0) -> 0 | CV38: =ROUND(SUM(CS38,CT38,CU38),2) -> 0 | CZ38: =ROUND(SUM(R38,AI38,CV38,CW38,CX38,CY38),2) -> 0 | DA38: =ROUND(CZ38/110*100,1) -> 0 | DB38: =IF(CZ38>=90,"A",IF(CZ38>=80,"B",IF(CZ38>=70,"C",IF(CZ38>=60,"D",IF(CZ38>0,"F"," "))))) | DE38: =IF(A38="","",DA38-ROW()/100000000)
B39: =IF(COUNTA(C3,D3,E3,F3,G3,H3,I3,J3,K3,L3,M3,N3,O3,P3,Q3)=0,"",COUNTA(C3,D3,E3,F3,G3,H3,I3,J3,K3,L3,M3,N3,O3,P3,Q3)) | R39: =IFERROR(SUM(C39,D39,E39,F39,G39,H39,I39,J39,K39,L39,M39,N39,O39,P39,Q39)/B39*30,0) -> 0 | S39: =IF(COUNTA(T3,U3,V3,W3,X3,Y3,Z3,AA3,AB3,AC3,AD3,AE3,AF3,AG3,AH3)=0,"",COUNTA(T3,U3,V3,W3,X3,Y3,Z3,AA3,AB3,AC3,AD3,AE3,AF3,AG3,AH3)) | AI39: =IFERROR(SUM(T39,U39,V39,W39,X39,Y39,Z39,AA39,AB39,AC39,AD39,AE39,AF39,AG39,AH39)/S39*30,0) -> 0 | AJ39: =IF(COUNTA(AK3,AN3,AQ3,AT3,AW3,AZ3,BC3,BF3,BI3,BL3,BO3,BR3,BU3,BX3,CA3,CD3,CG3,CJ3,CM3,CP3)=0,"",COUNTA(AK3,AN3,AQ3,AT3,AW3,AZ3,BC3,BF3,BI3,BL3,BO3,BR3,BU3,BX3,CA3,CD3,CG3,CJ3,CM3,CP3)) | CS39: =IFERROR(SUM(AK39,AN39,AQ39,AT39,AW39,AZ39,BC39,BF39,BI39,BL39,BO39,BR39,BU39,BX39,CA39,CD39,CG39,CJ39,CM39,CP39)/AJ39*10,0) -> 0 | CT39: =IFERROR(SUM(AL39,AO39,AR39,AU39,AX39,BA39,BD39,BG39,BJ39,BM39,BP39,BS39,BV39,BY39,CB39,CE39,CH39,CK39,CN39,CQ39)/AJ39/5*5,0) -> 0 | CU39: =IFERROR(SUM(AM39,AP39,AS39,AV39,AY39,BB39,BE39,BH39,BK39,BN39,BQ39,BT39,BW39,BZ39,CC39,CF39,CI39,CL39,CO39,CR39)/AJ39*5,0) -> 0 | CV39: =ROUND(SUM(CS39,CT39,CU39),2) -> 0 | CZ39: =ROUND(SUM(R39,AI39,CV39,CW39,CX39,CY39),2) -> 0 | DA39: =ROUND(CZ39/110*100,1) -> 0 | DB39: =IF(CZ39>=90,"A",IF(CZ39>=80,"B",IF(CZ39>=70,"C",IF(CZ39>=60,"D",IF(CZ39>0,"F"," "))))) | DE39: =IF(A39="","",DA39-ROW()/100000000)
B40: =IF(COUNTA(C3,D3,E3,F3,G3,H3,I3,J3,K3,L3,M3,N3,O3,P3,Q3)=0,"",COUNTA(C3,D3,E3,F3,G3,H3,I3,J3,K3,L3,M3,N3,O3,P3,Q3)) | R40: =IFERROR(SUM(C40,D40,E40,F40,G40,H40,I40,J40,K40,L40,M40,N40,O40,P40,Q40)/B40*30,0) -> 0 | S40: =IF(COUNTA(T3,U3,V3,W3,X3,Y3,Z3,AA3,AB3,AC3,AD3,AE3,AF3,AG3,AH3)=0,"",COUNTA(T3,U3,V3,W3,X3,Y3,Z3,AA3,AB3,AC3,AD3,AE3,AF3,AG3,AH3)) | AI40: =IFERROR(SUM(T40,U40,V40,W40,X40,Y40,Z40,AA40,AB40,AC40,AD40,AE40,AF40,AG40,AH40)/S40*30,0) -> 0 | AJ40: =IF(COUNTA(AK3,AN3,AQ3,AT3,AW3,AZ3,BC3,BF3,BI3,BL3,BO3,BR3,BU3,BX3,CA3,CD3,CG3,CJ3,CM3,CP3)=0,"",COUNTA(AK3,AN3,AQ3,AT3,AW3,AZ3,BC3,BF3,BI3,BL3,BO3,BR3,BU3,BX3,CA3,CD3,CG3,CJ3,CM3,CP3)) | CS40: =IFERROR(SUM(AK40,AN40,AQ40,AT40,AW40,AZ40,BC40,BF40,BI40,BL40,BO40,BR40,BU40,BX40,CA40,CD40,CG40,CJ40,CM40,CP40)/AJ40*10,0) -> 0 | CT40: =IFERROR(SUM(AL40,AO40,AR40,AU40,AX40,BA40,BD40,BG40,BJ40,BM40,BP40,BS40,BV40,BY40,CB40,CE40,CH40,CK40,CN40,CQ40)/AJ40/5*5,0) -> 0 | CU40: =IFERROR(SUM(AM40,AP40,AS40,AV40,AY40,BB40,BE40,BH40,BK40,BN40,BQ40,BT40,BW40,BZ40,CC40,CF40,CI40,CL40,CO40,CR40)/AJ40*5,0) -> 0 | CV40: =ROUND(SUM(CS40,CT40,CU40),2) -> 0 | CZ40: =ROUND(SUM(R40,AI40,CV40,CW40,CX40,CY40),2) -> 0 | DA40: =ROUND(CZ40/110*100,1) -> 0 | DB40: =IF(CZ40>=90,"A",IF(CZ40>=80,"B",IF(CZ40>=70,"C",IF(CZ40>=60,"D",IF(CZ40>0,"F"," "))))) | DE40: =IF(A40="","",DA40-ROW()/100000000)
...

Sheet Announcement Card
A1: N | B1: Name | C1: Committee | D1: Total | E1: GPA
A2: 1 | B2: =IFERROR(INDEX('Member Evaluation'!$A$5:$A$121,MATCH(LARGE('Member Evaluation'!$DE$5:$DE$121,1),'Member Evaluation'!$DE$5:$DE$121,0)),"") | C2: =IF(B2="","","OR") | D2: =IFERROR(INDEX('Member Evaluation'!$CZ$5:$CZ$121, MATCH(LARGE('Member Evaluation'!$DE$5:$DE$121, ROW(A1)), 'Member Evaluation'!$DE$5:$DE$121, 0)), "") | E2: =IFERROR(INDEX('Member Evaluation'!$DB$5:$DB$121,MATCH(LARGE('Member Evaluation'!$DE$5:$DE$121,1),'Member Evaluation'!$DE$5:$DE$121,0)),"")
A3: 2 | B3: =IFERROR(INDEX('Member Evaluation'!$A$5:$A$121,MATCH(LARGE('Member Evaluation'!$DE$5:$DE$121,2),'Member Evaluation'!$DE$5:$DE$121,0)),"") | C3: =IF(B3="","","OR") | D3: =IFERROR(INDEX('Member Evaluation'!$CZ$5:$CZ$121, MATCH(LARGE('Member Evaluation'!$DE$5:$DE$121, ROW(A2)), 'Member Evaluation'!$DE$5:$DE$121, 0)), "") | E3: =IFERROR(INDEX('Member Evaluation'!$DB$5:$DB$121,MATCH(LARGE('Member Evaluation'!$DE$5:$DE$121,2),'Member Evaluation'!$DE$5:$DE$121,0)),"")
A4: 3 | B4: =IFERROR(INDEX('Member Evaluation'!$A$5:$A$121,MATCH(LARGE('Member Evaluation'!$DE$5:$DE$121,3),'Member Evaluation'!$DE$5:$DE$121,0)),"") | C4: =IF(B4="","","OR") | D4: =IFERROR(INDEX('Member Evaluation'!$CZ$5:$CZ$121, MATCH(LARGE('Member Evaluation'!$DE$5:$DE$121, ROW(A3)), 'Member Evaluation'!$DE$5:$DE$121, 0)), "") | E4: =IFERROR(INDEX('Member Evaluation'!$DB$5:$DB$121,MATCH(LARGE('Member Evaluation'!$DE$5:$DE$121,3),'Member Evaluation'!$DE$5:$DE$121,0)),"")
A5: 4 | B5: =IFERROR(INDEX('Member Evaluation'!$A$5:$A$121,MATCH(LARGE('Member Evaluation'!$DE$5:$DE$121,4),'Member Evaluation'!$DE$5:$DE$121,0)),"") | C5: =IF(B5="","","OR") | D5: =IFERROR(INDEX('Member Evaluation'!$CZ$5:$CZ$121, MATCH(LARGE('Member Evaluation'!$DE$5:$DE$121, ROW(A4)), 'Member Evaluation'!$DE$5:$DE$121, 0)), "") | E5: =IFERROR(INDEX('Member Evaluation'!$DB$5:$DB$121,MATCH(LARGE('Member Evaluation'!$DE$5:$DE$121,4),'Member Evaluation'!$DE$5:$DE$121,0)),"")
A6: 5 | B6: =IFERROR(INDEX('Member Evaluation'!$A$5:$A$121,MATCH(LARGE('Member Evaluation'!$DE$5:$DE$121,5),'Member Evaluation'!$DE$5:$DE$121,0)),"") | C6: =IF(B6="","","OR") | D6: =IFERROR(INDEX('Member Evaluation'!$CZ$5:$CZ$121, MATCH(LARGE('Member Evaluation'!$DE$5:$DE$121, ROW(A5)), 'Member Evaluation'!$DE$5:$DE$121, 0)), "") | E6: =IFERROR(INDEX('Member Evaluation'!$DB$5:$DB$121,MATCH(LARGE('Member Evaluation'!$DE$5:$DE$121,5),'Member Evaluation'!$DE$5:$DE$121,0)),"")
A7: 6 | B7: =IFERROR(INDEX('Member Evaluation'!$A$5:$A$121,MATCH(LARGE('Member Evaluation'!$DE$5:$DE$121,6),'Member Evaluation'!$DE$5:$DE$121,0)),"") | C7: =IF(B7="","","OR") | D7: =IFERROR(INDEX('Member Evaluation'!$CZ$5:$CZ$121, MATCH(LARGE('Member Evaluation'!$DE$5:$DE$121, ROW(A6)), 'Member Evaluation'!$DE$5:$DE$121, 0)), "") | E7: =IFERROR(INDEX('Member Evaluation'!$DB$5:$DB$121,MATCH(LARGE('Member Evaluation'!$DE$5:$DE$121,6),'Member Evaluation'!$DE$5:$DE$121,0)),"")
A8: 7 | B8: =IFERROR(INDEX('Member Evaluation'!$A$5:$A$121,MATCH(LARGE('Member Evaluation'!$DE$5:$DE$121,7),'Member Evaluation'!$DE$5:$DE$121,0)),"") | C8: =IF(B8="","","OR") | D8: =IFERROR(INDEX('Member Evaluation'!$CZ$5:$CZ$121, MATCH(LARGE('Member Evaluation'!$DE$5:$DE$121, ROW(A7)), 'Member Evaluation'!$DE$5:$DE$121, 0)), "") | E8: =IFERROR(INDEX('Member Evaluation'!$DB$5:$DB$121,MATCH(LARGE('Member Evaluation'!$DE$5:$DE$121,7),'Member Evaluation'!$DE$5:$DE$121,0)),"")
A9: 8 | B9: =IFERROR(INDEX('Member Evaluation'!$A$5:$A$121,MATCH(LARGE('Member Evaluation'!$DE$5:$DE$121,8),'Member Evaluation'!$DE$5:$DE$121,0)),"") | C9: =IF(B9="","","OR") | D9: =IFERROR(INDEX('Member Evaluation'!$CZ$5:$CZ$121, MATCH(LARGE('Member Evaluation'!$DE$5:$DE$121, ROW(A8)), 'Member Evaluation'!$DE$5:$DE$121, 0)), "") | E9: =IFERROR(INDEX('Member Evaluation'!$DB$5:$DB$121,MATCH(LARGE('Member Evaluation'!$DE$5:$DE$121,8),'Member Evaluation'!$DE$5:$DE$121,0)),"")
A10: 9 | B10: =IFERROR(INDEX('Member Evaluation'!$A$5:$A$121,MATCH(LARGE('Member Evaluation'!$DE$5:$DE$121,9),'Member Evaluation'!$DE$5:$DE$121,0)),"") | C10: =IF(B10="","","OR") | D10: =IFERROR(INDEX('Member Evaluation'!$CZ$5:$CZ$121, MATCH(LARGE('Member Evaluation'!$DE$5:$DE$121, ROW(A9)), 'Member Evaluation'!$DE$5:$DE$121, 0)), "") | E10: =IFERROR(INDEX('Member Evaluation'!$DB$5:$DB$121,MATCH(LARGE('Member Evaluation'!$DE$5:$DE$121,9),'Member Evaluation'!$DE$5:$DE$121,0)),"")
A11: 10 | B11: =IFERROR(INDEX('Member Evaluation'!$A$5:$A$121,MATCH(LARGE('Member Evaluation'!$DE$5:$DE$121,10),'Member Evaluation'!$DE$5:$DE$121,0)),"") | C11: =IF(B11="","","OR") | D11: =IFERROR(INDEX('Member Evaluation'!$CZ$5:$CZ$121, MATCH(LARGE('Member Evaluation'!$DE$5:$DE$121, ROW(A10)), 'Member Evaluation'!$DE$5:$DE$121, 0)), "") | E11: =IFERROR(INDEX('Member Evaluation'!$DB$5:$DB$121,MATCH(LARGE('Member Evaluation'!$DE$5:$DE$121,10),'Member Evaluation'!$DE$5:$DE$121,0)),"")
A12: 11 | B12: =IFERROR(INDEX('Member Evaluation'!$A$5:$A$121,MATCH(LARGE('Member Evaluation'!$DE$5:$DE$121,11),'Member Evaluation'!$DE$5:$DE$121,0)),"") | C12: =IF(B12="","","OR") | D12: =IFERROR(INDEX('Member Evaluation'!$CZ$5:$CZ$121, MATCH(LARGE('Member Evaluation'!$DE$5:$DE$121, ROW(A11)), 'Member Evaluation'!$DE$5:$DE$121, 0)), "") | E12: =IFERROR(INDEX('Member Evaluation'!$DB$5:$DB$121,MATCH(LARGE('Member Evaluation'!$DE$5:$DE$121,11),'Member Evaluation'!$DE$5:$DE$121,0)),"")
A13: 12 | B13: =IFERROR(INDEX('Member Evaluation'!$A$5:$A$121,MATCH(LARGE('Member Evaluation'!$DE$5:$DE$121,12),'Member Evaluation'!$DE$5:$DE$121,0)),"") | C13: =IF(B13="","","OR") | D13: =IFERROR(INDEX('Member Evaluation'!$CZ$5:$CZ$121, MATCH(LARGE('Member Evaluation'!$DE$5:$DE$121, ROW(A12)), 'Member Evaluation'!$DE$5:$DE$121, 0)), "") | E13: =IFERROR(INDEX('Member Evaluation'!$DB$5:$DB$121,MATCH(LARGE('Member Evaluation'!$DE$5:$DE$121,12),'Member Evaluation'!$DE$5:$DE$121,0)),"")
A14: 13 | B14: =IFERROR(INDEX('Member Evaluation'!$A$5:$A$121,MATCH(LARGE('Member Evaluation'!$DE$5:$DE$121,13),'Member Evaluation'!$DE$5:$DE$121,0)),"") | C14: =IF(B14="","","OR") | D14: =IFERROR(INDEX('Member Evaluation'!$CZ$5:$CZ$121, MATCH(LARGE('Member Evaluation'!$DE$5:$DE$121, ROW(A13)), 'Member Evaluation'!$DE$5:$DE$121, 0)), "") | E14: =IFERROR(INDEX('Member Evaluation'!$DB$5:$DB$121,MATCH(LARGE('Member Evaluation'!$DE$5:$DE$121,13),'Member Evaluation'!$DE$5:$DE$121,0)),"")
A15: 14 | B15: =IFERROR(INDEX('Member Evaluation'!$A$5:$A$121,MATCH(LARGE('Member Evaluation'!$DE$5:$DE$121,14),'Member Evaluation'!$DE$5:$DE$121,0)),"") | C15: =IF(B15="","","OR") | D15: =IFERROR(INDEX('Member Evaluation'!$CZ$5:$CZ$121, MATCH(LARGE('Member Evaluation'!$DE$5:$DE$121, ROW(A14)), 'Member Evaluation'!$DE$5:$DE$121, 0)), "") | E15: =IFERROR(INDEX('Member Evaluation'!$DB$5:$DB$121,MATCH(LARGE('Member Evaluation'!$DE$5:$DE$121,14),'Member Evaluation'!$DE$5:$DE$121,0)),"")
A16: 15 | B16: =IFERROR(INDEX('Member Evaluation'!$A$5:$A$121,MATCH(LARGE('Member Evaluation'!$DE$5:$DE$121,15),'Member Evaluation'!$DE$5:$DE$121,0)),"") | C16: =IF(B16="","","OR") | D16: =IFERROR(INDEX('Member Evaluation'!$CZ$5:$CZ$121, MATCH(LARGE('Member Evaluation'!$DE$5:$DE$121, ROW(A15)), 'Member Evaluation'!$DE$5:$DE$121, 0)), "") | E16: =IFERROR(INDEX('Member Evaluation'!$DB$5:$DB$121,MATCH(LARGE('Member Evaluation'!$DE$5:$DE$121,15),'Member Evaluation'!$DE$5:$DE$121,0)),"")
A17: 16 | B17: =IFERROR(INDEX('Member Evaluation'!$A$5:$A$121,MATCH(LARGE('Member Evaluation'!$DE$5:$DE$121,16),'Member Evaluation'!$DE$5:$DE$121,0)),"") | C17: =IF(B17="","","OR") | D17: =IFERROR(INDEX('Member Evaluation'!$CZ$5:$CZ$121, MATCH(LARGE('Member Evaluation'!$DE$5:$DE$121, ROW(A16)), 'Member Evaluation'!$DE$5:$DE$121, 0)), "") | E17: =IFERROR(INDEX('Member Evaluation'!$DB$5:$DB$121,MATCH(LARGE('Member Evaluation'!$DE$5:$DE$121,16),'Member Evaluation'!$DE$5:$DE$121,0)),"")
A18: 17 | B18: =IFERROR(INDEX('Member Evaluation'!$A$5:$A$121,MATCH(LARGE('Member Evaluation'!$DE$5:$DE$121,17),'Member Evaluation'!$DE$5:$DE$121,0)),"") | C18: =IF(B18="","","OR") | D18: =IFERROR(INDEX('Member Evaluation'!$CZ$5:$CZ$121, MATCH(LARGE('Member Evaluation'!$DE$5:$DE$121, ROW(A17)), 'Member Evaluation'!$DE$5:$DE$121, 0)), "") | E18: =IFERROR(INDEX('Member Evaluation'!$DB$5:$DB$121,MATCH(LARGE('Member Evaluation'!$DE$5:$DE$121,17),'Member Evaluation'!$DE$5:$DE$121,0)),"")
A19: 18 | B19: =IFERROR(INDEX('Member Evaluation'!$A$5:$A$121,MATCH(LARGE('Member Evaluation'!$DE$5:$DE$121,18),'Member Evaluation'!$DE$5:$DE$121,0)),"") | C19: =IF(B19="","","OR") | D19: =IFERROR(INDEX('Member Evaluation'!$CZ$5:$CZ$121, MATCH(LARGE('Member Evaluation'!$DE$5:$DE$121, ROW(A18)), 'Member Evaluation'!$DE$5:$DE$121, 0)), "") | E19: =IFERROR(INDEX('Member Evaluation'!$DB$5:$DB$121,MATCH(LARGE('Member Evaluation'!$DE$5:$DE$121,18),'Member Evaluation'!$DE$5:$DE$121,0)),"")
A20: 19 | B20: =IFERROR(INDEX('Member Evaluation'!$A$5:$A$121,MATCH(LARGE('Member Evaluation'!$DE$5:$DE$121,19),'Member Evaluation'!$DE$5:$DE$121,0)),"") | C20: =IF(B20="","","OR") | D20: =IFERROR(INDEX('Member Evaluation'!$CZ$5:$CZ$121, MATCH(LARGE('Member Evaluation'!$DE$5:$DE$121, ROW(A19)), 'Member Evaluation'!$DE$5:$DE$121, 0)), "") | E20: =IFERROR(INDEX('Member Evaluation'!$DB$5:$DB$121,MATCH(LARGE('Member Evaluation'!$DE$5:$DE$121,19),'Member Evaluation'!$DE$5:$DE$121,0)),"")
A21: 20 | B21: =IFERROR(INDEX('Member Evaluation'!$A$5:$A$121,MATCH(LARGE('Member Evaluation'!$DE$5:$DE$121,20),'Member Evaluation'!$DE$5:$DE$121,0)),"") | C21: =IF(B21="","","OR") | D21: =IFERROR(INDEX('Member Evaluation'!$CZ$5:$CZ$121, MATCH(LARGE('Member Evaluation'!$DE$5:$DE$121, ROW(A20)), 'Member Evaluation'!$DE$5:$DE$121, 0)), "") | E21: =IFERROR(INDEX('Member Evaluation'!$DB$5:$DB$121,MATCH(LARGE('Member Evaluation'!$DE$5:$DE$121,20),'Member Evaluation'!$DE$5:$DE$121,0)),"")
A22: 21 | B22: =IFERROR(INDEX('Member Evaluation'!$A$5:$A$121,MATCH(LARGE('Member Evaluation'!$DE$5:$DE$121,21),'Member Evaluation'!$DE$5:$DE$121,0)),"") | C22: =IF(B22="","","OR") | D22: =IFERROR(INDEX('Member Evaluation'!$CZ$5:$CZ$121, MATCH(LARGE('Member Evaluation'!$DE$5:$DE$121, ROW(A21)), 'Member Evaluation'!$DE$5:$DE$121, 0)), "") | E22: =IFERROR(INDEX('Member Evaluation'!$DB$5:$DB$121,MATCH(LARGE('Member Evaluation'!$DE$5:$DE$121,21),'Member Evaluation'!$DE$5:$DE$121,0)),"")
A23: 22 | B23: =IFERROR(INDEX('Member Evaluation'!$A$5:$A$121,MATCH(LARGE('Member Evaluation'!$DE$5:$DE$121,22),'Member Evaluation'!$DE$5:$DE$121,0)),"") | C23: =IF(B23="","","OR") | D23: =IFERROR(INDEX('Member Evaluation'!$CZ$5:$CZ$121, MATCH(LARGE('Member Evaluation'!$DE$5:$DE$121, ROW(A22)), 'Member Evaluation'!$DE$5:$DE$121, 0)), "") | E23: =IFERROR(INDEX('Member Evaluation'!$DB$5:$DB$121,MATCH(LARGE('Member Evaluation'!$DE$5:$DE$121,22),'Member Evaluation'!$DE$5:$DE$121,0)),"")
